Workbook

Sheet Данные 
A1: Город | B1: Провайдер | C1: На кого оформлен | D1: Номер договора | E1: Телефон | F1: ЛК
A2: Тюмень | B2: Эр-телеком холдинг | C2: ООО Безопасный город | D2: ФК5610 | E2: 88003332444 | F2: https://auth.dom.ru/auth/realms/user/protocol/openid-connect/auth?response_type=code&redirect_uri=https%3A%2F%2Fnewlkb2b.dom.ru%2Flk&client_id=lkb2b&nonce=7c18d7d140f36a1abe642da98ff7fdce&state=0e9862fd05f45efee6156aa126019c4d&scope=openid | G2: spirina@gorod.expert | H2: wy6f04wh
A3: Тюмень | B3: Позитив | C3: ООО Безопасный город | D3: 00-0655 от 19.05.2022 | E3: 8-3452-56-22-26 | F3: https://lk.pozitivtelecom.ru/accounts/00-0655/details | G3: v295334 | H3: 2953347
A4: Тюмень | B4: Ростелеком | C4: Сафиуллин Раниф | F4: https://b2c.passport.rt.ru/auth/realms/b2c/login-actions/authenticate?execution=fc343b3b-9ff7-4786-bb30-e60caa7821cd&client_id=lk_b2c&tab_id=42XYkA7yKv0 | G4: 7 905 375-48-65 | H4: K.3XK3u*jp73#yL
A5: Тюмень | B5: Дом.ру | C5: Ссылка для входа в ЛК физ.лица | E5: 88003332444 | F5: https://tmn.dom.ru/user/login?referrer=/lk&utm_referrer=https://yandex.ru/ | G5: индивидуальные данные
A6: Зеленодольск | B6: Интердол | C6: ООО Сектор безопасности | D6: 16966-06-2021 | E6: 8-84371-9-30-00
A7: Казань | B7: Йота | C7: Сафиуллин Раниф | F7: https://lk.yota.ru/devices | G7: 89053754865 | H7: Gmail.com7a!
A8: Казань | B8: Йота | C8: Якупов Марат | F8: https://my.yota.ru/devices | G8: 89600343630 | H8: Marat2021!
B9: МТС юр лицо | C9: Сафиуллин Раниф | F9: https://lk-b2b.mts.ru/mts_business_web/history
B10: Татаиснефть | E10: 8 (8553) 30‑50-00
B11: МТС | E11: 8 (800) 250-08-90
B12: Ростелеком (РТК) | E12: 8 (800) 100-08-00
B13: Казгорсеть (КГС) | E13: 8 (843) 209-02-09 | F13: нажать 2, затем 2
B14: Таттелеком | E14: 8 (843) 222-22-22
B15: Дом.ру | E15: 8 (800) 707-42-19 | F15: 88003332444- тех. поддержка
B16: ОНИКС | E16: 89270369393

Sheet Альметьевск
B1: Кол-во | C1: Адреса и где находится шкаф в примечании | D1: Кол-во подъездов | E1: Ссылки на роутер | F1: УК | G1: ФИО | H1: Оператор | I1: Договор, логин и пароль в примечании | J1: Что установлено | K1: Дата списание | L1: Тариф | M1: оплата в декабре | O1: Оплата в ноябре | Q1: оплата в октябре | S1: оплата в сентябре | U1: оплата в августе | W1: оплата в июле | Y1: оплата в июне | AA1: Оплата в мае | AC1: ОПЛАТА В АПРЕЛЕ | AE1: ОПЛАТА В МАРТЕ | AG1: Оплата в феврале | AI1: Оплата в январе
A2: 1 | B2: 1 | C2: Галеева 4 | D2: 1 | E2: http://78.138.177.251:8888 | F2: Алсу | G2: Фадеев Вячеслав Александрович кв.5, 8(987)230-64-09 | H2: Таттелеком | I2: 103887738 | J2: Камеры | K2: 30 числа | L2: 590 | M2: 590 | N2: 46009 | O2: 590 | P2: 45980 | Q2: 590 | R2: 45947 | S2: 590 | T2: 45919 | U2: 590 | V2: 590 | W2: 590 | X2: 45861 | Y2: 590 | Z2: 45827 | AA2: 590 | AB2: 45797 | AC2: 590 | AD2: 45763 | AE2: 590 | AF2: 45735 | AG2: 590 | AH2: 45706 | AI2: 590 | AJ2: 45678
A3: 2 | B3: 2 | C3: Галеева 8 | D3: 6 | E3: http://217.173.19.66:81 | F3: Алсу | G3: Фаракшин Фарит Минакдясович кв.102, +7 (999) 169-08-64 | H3: МТС | I3: 31039503035 | J3: Камеры | K3: до 6 числа | L3: 830 | M3: 830 | N3: 46009 | O3: 830 | P3: 45979 | Q3: 830 | R3: 45947 | S3: 830 | T3: 45919 | U3: 830 | V3: 830 | W3: 830 | X3: 45861 | Y3: 830 | Z3: 45827 | AA3: 830 | AB3: 45797 | AC3: 830 | AD3: 45764 | AE3: 830 | AF3: 45735 | AG3: 830 | AH3: 45706 | AI3: 830 | AJ3: 45678
A4: 3 | B4: 3 | C4: Галеева 10 | D4: 6 | E4: http://178.207.9.103 | F4: Алсу | G4: Нуриахмедов Талгат Марсович кв.1, +7 (917) 233-15-29 | H4: Таттелеком | I4: 103862466 | J4: Камеры | K4: 25 числа | L4: 900 | M4: 900 | N4: 46009 | O4: 900 | P4: 45980 | Q4: 900 | R4: 45947 | S4: 900 | T4: 45923 | U4: 0 | V4: 0 | W4: 0 | Y4: 0 | AA4: 0 | AC4: 0 | AE4: 0 | AG4: 0 | AI4: 0
A5: 4 | B5: 4 | C5: Галеева 22 | D5: 5 | E5: http://78.138.174.236:8080 | F5: Алсу | G5: Маннанов Марсель Забирович, кв.1, .8 9870627535 | H5: Таттелеком | I5: 105 408 289 от 30.12.19 | J5: Камеры | K5: 25 числа | L5: 690 | M5: 690 | N5: 46009 | O5: 690 | P5: 45980 | Q5: 690 | R5: 45947 | S5: 690 | T5: 45919 | U5: 660 | V5: 660 | W5: 660 | X5: 45861 | Y5: 660 | Z5: 45827 | AA5: 0 | AC5: 650 | AD5: 45763 | AE5: 660 | AF5: 45735 | AG5: 660 | AH5: 45706 | AI5: 660 | AJ5: 45678
A6: 5 | B6: 5 | C6: Галеева 23 | D6: 11 | E6: http://178.207.12.175 | F6: Алсу | G6: Валиева Резеда Рависовна кв.191, звонить ей - 89991692785 (посл раз при звонке муж сказал звонить ей 8 (919) 631-11-60 номер ее мужа. | H6: Таттелеком | I6: 101778152 | J6: Спутник, Камеры | K6: 25 числа | L6: абон.плата 800 руб. в месяц+50р =920 | M6: 920 | N6: 46009 | O6: 920 | P6: 45980 | Q6: 920 | R6: 45947 | S6: 920 | T6: 45919 | U6: 920 | V6: 920 | W6: 920 | X6: 45861 | Y6: 920 | Z6: 45827 | AA6: 920 | AB6: 45797 | AC6: 920 | AD6: 45763 | AE6: 920 | AF6: 45735 | AG6: 920 | AH6: 45706 | AI6: 920 | AJ6: 45678
A7: 6 | B7: 6 | C7: Галеева 25 | D7: 10 | E7: http://178.207.12.220 | F7: Алсу | G7: Зиганшина Ляйсан Илсуровна кв.123, 8(927)455-35-55 | H7: Таттелеком | I7: 101032467 | J7: Камеры | K7: 25 числа | L7: АБ. опл.795 р. без рассрочки, 3227р. с рассрочкой | M7: 795 | N7: 46009 | O7: 795 | P7: 45980 | Q7: 795 | R7: 45947 | S7: 795 | T7: 45919 | U7: 795 | V7: 795 | W7: 795 | X7: 45861 | Y7: 795 | Z7: 45827 | AA7: 795 | AB7: 45797 | AC7: 795 | AD7: 45763 | AE7: 795 | AF7: 45735 | AG7: 795 | AH7: 45706 | AI7: 795 | AJ7: 45678
A8: 7 | B8: 7 | C8: Галеева 27 | D8: 9 | E8: http://185.148.216.67 | F8: Алсу | G8: Сальцин Алексей В. кв.122, 8(927)424-24-33 | H8: Татаиснефть | I8: 104 73 29 | J8: Спутник, Камеры | K8: до 25 числа | L8: 905р. | M8: 905 | N8: 46009 | O8: 905 | P8: 45980 | Q8: 905 | R8: 45947 | S8: 905 | T8: 45919 | U8: 905 | V8: 905 | W8: 905 | X8: 45861 | Y8: 905 | Z8: 45826 | AA8: 905 | AB8: 45797 | AC8: 905 | AD8: 45763 | AE8: 905 | AF8: 45735 | AG8: 905 | AH8: 45706 | AI8: 905 | AJ8: 45678
A9: 8 | B9: 8 | C9: Галеева 29 | D9: 9 | E9: http://178.207.12.177:8080 | F9: Алсу | G9: Крифтиков Николай Николаевич | H9: Таттелеком | I9: 102570522 | J9: Камеры | K9: 25 числа | L9: 920 | M9: 920 | N9: 46009 | O9: 920 | P9: 45980 | Q9: 920 | R9: 45947 | S9: 920 | T9: 45919 | U9: 920 | V9: 920 | W9: 890 | X9: 45861 | Y9: 890 | Z9: 45827 | AA9: 890 | AB9: 45797 | AC9: 890 | AD9: 45763 | AE9: 890 | AF9: 45735 | AG9: 890 | AH9: 45706 | AI9: 890 | AJ9: 45678
A10: 9 | B10: 9 | C10: Галеева 31 | D10: 9 | E10: http://217.173.17.173 | F10: Алсу | G10: Рафикова Альбина Георгиевна кв.82, 89872836671 | H10: МТС | I10: 310 391 39 074 | J10: Спутник, Камеры | K10: до 15 числа | L10: 700 | M10: 700 | O10: 700 | Q10: 700 | R10: 45976 | S10: 700 | T10: 45919 | U10: 700 | W10: 700 | Y10: 700 | Z10: 45853 | AA10: 1400 | AB10: 45823 | AC10: 700 | AD10: 45764 | AE10: 0 | AG10: 1400 | AH10: 45706 | AI10: 700 | AJ10: 45667
A11: 10 | B11: 10 | C11: Галеева 33 | D11: 9 | E11: http://217.173.17.191 | F11: Алсу | G11: Ахметшин Нияз Зуфарович | H11: МТС | I11: 310 392 679 03 | J11: Спутник, Камеры | K11: до 25 числа | L11: 1069 | M11: 1069 | N11: 46009 | O11: 1069 | P11: 45979 | Q11: 1069 | R11: 45947 | S11: 1069 | T11: 45919 | U11: 1069 | V11: 1069 | W11: 1069 | X11: 45861 | Y11: 1069 | Z11: 45827 | AA11: 1069 | AB11: 45797 | AC11: 1069 | AD11: 45764 | AE11: 1069 | AF11: 45735 | AG11: 1069 | AH11: 45706 | AI11: 1069 | AJ11: 45678
A12: 11 | B12: 11 | C12: Галеева 35 | D12: 9 | E12: http://78.138.190.178/ | F12: Алсу | G12: Миргазитов Алмаз Ирекович кв 234 | H12: Таттелеком | I12: 105 911 370 | J12: Камеры | K12: 25 числа | L12: 549 | M12: 549 | N12: 46009 | O12: 549 | P12: 45980 | Q12: 549 | R12: 45947 | S12: 549 | T12: 45919 | U12: 549 | V12: 549 | W12: 549 | X12: 45861 | Y12: 549 | Z12: 45827 | AA12: 549 | AB12: 45797 | AC12: 549 | AD12: 45763 | AE12: 549 | AF12: 45735 | AG12: 549 | AH12: 45706 | AI12: 549 | AJ12: 45678
A13: 12 | B13: 12 | C13: Гафиатуллина 62 | D13: 2 | E13: http://185.148.216.28:8080/ | F13: Алсу | G13: Гатауллин Марсель Валиаметович, кв. 36, 89274708700 | H13: Татаиснефть | I13: 1060523 | J13: Спутник, Камеры | L13: 440 | M13: 440 | N13: 46009 | O13: 440 | P13: 45980 | Q13: 440 | R13: 45947 | S13: 440 | T13: 45919 | U13: 440 | V13: 440 | W13: 440 | X13: 45861 | Y13: 440 | Z13: 45826 | AA13: 440 | AB13: 45797 | AC13: 440 | AD13: 45763 | AE13: 440 | AF13: 45735 | AG13: 440 | AH13: 45706 | AI13: 440 | AJ13: 45678
A14: 21 | B14: 20 | C14: Ленина 106 | D14: 2 | F14: Алсу | G14: 89869007887 | H14: МТС | J14: Спутник | K14: до 24 числа | L14: 800 | M14: 800 | N14: 46009 | O14: 800 | P14: 45980 | Q14: 800 | R14: 45947 | S14: 800 | T14: 45919 | U14: 800 | V14: 800 | W14: 800 | X14: 45861 | Y14: 800 | Z14: 45827 | AA14: 800 | AB14: 45797 | AC14: 800 | AD14: 45764 | AE14: 800 | AF14: 45735 | AG14: 800 | AH14: 45706 | AI14: 800 | AJ14: 45678
A15: 22 | B15: 21 | C15: Ленина 147 | D15: 2 | F15: Алсу | G15: Кадыров Радик Халитович, 8917 270 93 90 | H15: МТС | I15: 216300440448 | J15: Спутник | L15: 870 | M15: 870 | N15: 46009 | O15: 870 | P15: 45980 | Q15: 870 | R15: 45947 | S15: 870 | T15: 45919 | U15: 870 | V15: 870 | W15: 870 | X15: 45861 | Y15: 870 | Z15: 45827 | AA15: 870 | AB15: 45797 | AC15: 870 | AD15: 45764 | AE15: 870 | AF15: 45735 | AG15: 870 | AH15: 45706 | AI15: 870 | AJ15: 45678
A16: 23 | B16: 22 | C16: Ленина 143 | D16: 4 | F16: Алсу | G16: Зигангирова Регина Фархатовна, 89625743377 | H16: Таттелеком | I16: 102137106 | J16: Спутник | K16: 25 числа | L16: 550 | M16: 550 | N16: 46009 | O16: 550 | P16: 45980 | Q16: 550 | R16: 45947 | S16: 550 | T16: 45919 | U16: 550 | V16: 550 | W16: 550 | X16: 45861 | Y16: 550 | Z16: 45827 | AA16: 550 | AB16: 45797 | AC16: 550 | AD16: 45763 | AE16: 550 | AF16: 45735 | AG16: 550 | AH16: 45706 | AI16: 550 | AJ16: 45678
A17: 20 | B17: 23 | C17: Ленина 157 А | D17: 2 | E17: http://178.207.13.192:8080 | F17: Алсу | G17: Кучкина Светлана. кв. 40, домофон 2402, 8(960)059-92-18 | H17: Таттелеком | I17: 102241141 | J17: Спутник, Камеры | K17: 25 числа | L17: 810 | M17: 810 | N17: 46009 | O17: 810 | P17: 45980 | Q17: 810 | R17: 45947 | S17: 640 | T17: 45919 | U17: 640 | V17: 640 | W17: 640 | X17: 45861 | Y17: 640 | Z17: 45827 | AA17: 640 | AB17: 45797 | AC17: 640 | AD17: 45763 | AE17: 640 | AF17: 45735 | AG17: 640 | AH17: 45706 | AI17: 640 | AJ17: 45678
A18: 21 | B18: 24 | C18: Нефтяников 11А | D18: 1 | E18: http://185.148.219.161 | F18: Алсу | G18: Аюпов Сергей Александрович кв 12 89874207630 | H18: Татаиснефть | I18: 10 52 354 | J18: Камеры | K18: до 25 числа | L18: 350 | M18: 350 | N18: 46009 | O18: 350 | P18: 45980 | Q18: 350 | R18: 45947 | S18: 350 | T18: 45919 | U18: 350 | V18: 350 | W18: 350 | X18: 45861 | Y18: 350 | Z18: 45826 | AA18: 350 | AB18: 45797 | AC18: 350 | AD18: 45763 | AE18: 350 | AF18: 45735 | AG18: 350 | AH18: 45706 | AI18: 350 | AJ18: 45678
A19: 26 | B19: 25 | C19: Нефтяников 17 | D19: 3 | F19: Алсу | G19: Елесеева Дарья Владимировна | H19: МТС | J19: Спутник | L19: 500 | M19: 500 | N19: 46009 | O19: 500 | P19: 45980 | Q19: 500 | R19: 45947 | S19: 500 | T19: 45919 | U19: 500 | V19: 500 | W19: 500 | X19: 45861 | Y19: 500 | Z19: 45827 | AA19: 500 | AB19: 45797 | AC19: 500 | AD19: 45764 | AE19: 500 | AF19: 45735 | AG19: 500 | AH19: 45706 | AI19: 500 | AJ19: 45678
A20: 22 | B20: 26 | C20: Нефтяников 35 | D20: 4 | E20: http://neftyanikov35.keenetic.link | F20: Алсу | G20: Васильев Богдан | H20: Таттелеком | I20: 107172579 | J20: Спутник, Камеры | K20: 25 числа | L20: 470 | M20: 470 | N20: 46009 | O20: 470 | P20: 45980 | Q20: 470 | R20: 45947 | S20: 470 | T20: 45919 | U20: 470 | V20: 470 | W20: 470 | X20: 45861 | Y20: 470 | Z20: 45827 | AA20: 470 | AB20: 45797 | AC20: 450 | AD20: 45763 | AE20: 450 | AF20: 45735 | AG20: 450 | AH20: 45706 | AI20: 450 | AJ20: 45678
A21: 24 | B21: 27 | C21: Строителей 61 | D21: 1 | E21: http://178.207.12.187 | F21: Алсу | G21: Новикова Лилия Раисовна кв.12, 89503138559 | H21: Таттелеком | I21: 106 350 692 | J21: Камеры | K21: 25 числа | L21: 981 | M21: 981 | N21: 46009 | O21: 981 | P21: 45980 | Q21: 981 | R21: 45947 | S21: 981 | T21: 45919 | U21: 981 | V21: 981 | W21: 981 | X21: 45861 | Y21: 981 | Z21: 45827 | AA21: 981 | AB21: 45797 | AC21: 981 | AD21: 45763 | AE21: 981 | AF21: 45735 | AG21: 981 | AH21: 45706 | AI21: 981 | AJ21: 45678
A22: 25 | C22: Строителей 53б | D22: 3 | F22: Алсу | G22: Ананьева Олеся Владимировна, кв 63 89172239401 | H22: Таттелеком | I22: 107456908 | J22: камеры, спутники | K22: 8 числа | L22: 750 | M22: 750 | O22: 750 | Q22: 750 | R22: 45960 | S22: 750 | U22: 750 | W22: 750 | Y22: 750 | Z22: 45846 | AA22: 750 | AB22: 45816 | AC22: =530+650 -> 1180 | AD22: 45763 | AF22: 45729
A23: 26 | B23: 28 | C23: Строителей 68 | D23: 7 | E23: http://78.138.190.21/ | F23: Алсу | G23: кв.265 Халилова Марина Игоревна | H23: Таттелеком | I23: 100 726 004 | J23: Спутник, Камеры | K23: 25 числа | L23: 693 | M23: 693 | N23: 46009 | O23: 693 | P23: 45980 | Q23: 693 | R23: 45947 | S23: 693 | T23: 45919 | U23: 693 | V23: 693 | W23: 693 | X23: 45861 | Y23: 693 | Z23: 45827 | AA23: 693 | AB23: 45797 | AC23: 693 | AD23: 45763 | AE23: 693 | AF23: 45735 | AG23: 693 | AH23: 45706 | AI23: 693 | AJ23: 45678
A24: 27 | C24: Строителей 70 | D24: 1 | F24: Алсу | G24: Замалиев Руслан Ришатович, 89867124313 | H24: МТС | I24: 31033300970 | J24: Камеры | K24: 08 числа | L24: 850 | M24: 850 | O24: 790 | Q24: 790 | S24: 790 | T24: 45919 | U24: 790 | W24: 790 | Y24: 790 | Z24: 45845 | AA24: 790 | AB24: 45815 | AC24: 790 | AD24: 45764 | AE24: 790 | AF24: 45735 | AG24: 470 | AH24: 45706 | AI24: 320 | AJ24: 45678
A25: 28 | C25: Строителей 74 | D25: 5 | F25: Алсу | G25: Кропачева Алия Рафаэльевна , кв 36 | H25: Таттелеком | I25: 107516355 | J25: Камеры | K25: 25 числа | L25: 550 | M25: 550 | N25: 46009 | O25: 550 | P25: 45980 | Q25: 550 | R25: 45947 | S25: 550 | T25: 45919 | U25: 550 | V25: 550 | W25: 550 | X25: 45861 | Y25: 550 | Z25: 45827 | AA25: 550 | AB25: 45797 | AC25: 550 | AD25: 45763 | AE25: 550 | AF25: 45735 | AG25: 550 | AH25: 45706 | AI25: 550 | AJ25: 45678
A26: 29 | C26: Строителей 78 | D26: 4 | F26: Алсу | G26: Булатова Альбина Рамилевна, кв 118 | H26: Таттелеком | I26: 104717269 | J26: Камеры | K26: 25 числа | L26: 590 | M26: 590 | N26: 46009 | O26: 590 | P26: 45980 | Q26: 590 | R26: 45947 | S26: 590 | T26: 45919 | U26: 590 | V26: 590 | W26: 590 | X26: 45861 | Y26: 590 | Z26: 45827 | AA26: 590 | AB26: 45797 | AC26: 590 | AD26: 45763 | AE26: 590 | AF26: 45735 | AG26: 590 | AH26: 45706 | AI26: 590 | AJ26: 45678
A27: 30 | B27: 31 | C27: Строителей 76 | D27: 6 | E27: https://stroitelei76.keenetic.link/ | F27: Алсу | G27: Фролов Геннадий Александрович, кв 230 +79393775392 | H27: Татаиснефть | I27: 105 96 65 | J27: Камеры | K27: 25 числа | L27: 670 | M27: 670 | N27: 46009 | O27: 670 | P27: 45980 | Q27: 670 | R27: 45947 | S27: 670 | T27: 45919 | U27: 490 | V27: 490 | W27: 490 | X27: 45861 | Y27: 490 | Z27: 45826 | AA27: 490 | AB27: 45797 | AC27: 490 | AD27: 45763 | AE27: 490 | AF27: 45735 | AG27: 490 | AH27: 45706 | AI27: 490 | AJ27: 45678
A28: 31 | B28: 32 | C28: Строителей 80 | D28: 6 | E28: http://178.207.15.106:8080 | F28: Алсу | G28: Крымский Дамир Рафаэльевич | H28: Таттелеком | I28: 105 831 706 | J28: Камеры | K28: 25 числа | L28: 649 | M28: 649 | N28: 46009 | O28: 649 | P28: 45980 | Q28: 649 | R28: 45947 | S28: 649 | T28: 45919 | U28: 649 | V28: 649 | W28: 649 | X28: 45861 | Y28: 649 | Z28: 45827 | AA28: 649 | AB28: 45797 | AC28: 649 | AD28: 45763 | AE28: 649 | AF28: 45735 | AG28: 649 | AH28: 45706 | AI28: 649 | AJ28: 45678
A29: 32 | B29: 33 | C29: Чернышевского 46а | D29: 2 | E29: http://178.207.8.74 | F29: Алсу | G29: Хаббулина Рамиля Мохаметкасимовна, 89869135351 | H29: Таттелеком | I29: 104080067 | J29: Камеры | K29: 25 числа | L29: 795 | M29: 750 | N29: 46009 | O29: 750 | P29: 45980 | Q29: 750 | R29: 45947 | S29: 750 | T29: 45919 | U29: 750 | V29: 750 | W29: 750 | X29: 45861 | Y29: 720 | Z29: 45827 | AA29: 720 | AB29: 45797 | AC29: 720 | AD29: 45763 | AE29: 720 | AF29: 45735 | AG29: 720 | AH29: 45706 | AI29: 720 | AJ29: 45678
A30: 33 | B30: 34 | C30: Новикова 1 | D30: 6 | E30: http://178.207.8.118:8080 | F30: Алсу | G30: Кузнецов Артем Степанович | H30: Таттелеком | I30: 106124091 | J30: Спутник, Камеры | K30: 25 числа | L30: 580 | M30: 580 | N30: 46009 | O30: 580 | P30: 45980 | Q30: 580 | R30: 45947 | S30: 580 | T30: 45919 | U30: 580 | V30: 580 | W30: 580 | X30: 45861 | Y30: 580 | Z30: 45827 | AA30: 580 | AB30: 45797 | AC30: 459 | AD30: 45763 | AE30: 459 | AF30: 45735 | AG30: 459 | AH30: 45706 | AI30: 459 | AJ30: 45678
A31: 34 | C31: Олимпик лайф 2 Гафиатул 60 | F31: Алсу | G31: Якупов Марат | H31: Йота | L31: 850 | M31: 850 | N31: 46009 | O31: 0 | Q31: 850 | R31: 45947 | S31: 850 | T31: 45919 | U31: 850 | V31: 45889 | W31: 850 | X31: 45861 | Y31: 850 | Z31: 45826 | AA31: 850 | AB31: 45797
A32: 40 | B32: 35 | C32: Шевченко 116 | F32: Алсу | G32: Калимуллин Раиль Гаптрашитович кв 41 89173936018 | H32: МТС | J32: Спутник | K32: 10 числа | L32: 925 | M32: 925 | O32: 925 | Q32: 925 | S32: 925 | T32: 45919 | U32: 925 | W32: 925 | Y32: 925 | Z32: 45848 | AA32: 1680 | AB32: 45818 | AC32: 840 | AD32: 45763 | AE32: 840 | AF32: 45735 | AG32: 840 | AH32: 45706 | AI32: 840 | AJ32: 45678
A33: 13 | B33: 13 | C33: Гафиатуллина 66 | D33: 4 | E33: http://217.173.19.42:8080/ | F33: Альмет | G33: Сания Зуфаровна Х | H33: МТС | J33: Спутник, Камеры | L33: 989 | M33: 989 | N33: 46009 | O33: 989 | P33: 45979 | Q33: 989 | R33: 45947 | S33: 989 | T33: 45919 | U33: 989 | V33: 989 | W33: 750 | X33: 45857 | Y33: 750 | Z33: 45827 | AA33: 750 | AB33: 45797 | AC33: 750 | AD33: 45764 | AE33: 750 | AF33: 45735 | AG33: 750 | AH33: 45706 | AI33: 750 | AJ33: 45678
A34: 13 | B34: 13 | C34: Гафиатуллина 66 | D34: 4 | E34: http://217.173.19.42:8080/ | F34: Альмет | H34: МТС (юр лицо) | I34: в лк брать счет | J34: Спутник, Камеры | K34: ? | L34: ?
A35: 14 | B35: 14 | C35: Зарипова 5 | D35: 2 | E35: http://217.173.17.140:8080 | F35: Альмет | G35: Муфазарова Эльвира Жоробаева, кв 28, | H35: МТС | I35: 31030631761 | J35: Спутник, Камеры | L35: 1070 | M35: 1071 | N35: 46009 | O35: 1070 | P35: 45979 | Q35: 1070 | R35: 45947 | S35: 1070 | T35: 45919 | U35: 965 | V35: 965 | W35: 965 | X35: 45861 | Y35: 965 | Z35: 45826 | AA35: 965 | AB35: 45797 | AC35: 965 | AD35: 45763 | AE35: 965 | AF35: 45735 | AG35: 0 | AI35: 915
A36: 15 | B36: 15 | C36: Зарипова 11 | D36: 2 | E36: http://185.148.216.4 | F36: Альмет | G36: Яруллин Фарит кв.39, 8(917)234-70-60 | H36: Татаиснефть | I36: 104 83 60 | J36: Спутник, Камеры | K36: 1 числа | L36: 695р. | M36: 695 | N36: 46009 | O36: 695 | P36: 45980 | Q36: 695 | R36: 45947 | S36: 695 | T36: 45919 | U36: 695 | V36: 695 | W36: 695 | X36: 45861 | Y36: 695 | Z36: 45826 | AA36: 695 | AB36: 45797 | AC36: 695 | AD36: 45763 | AE36: 695 | AF36: 45735 | AG36: 695 | AH36: 45706 | AI36: 695 | AJ36: 45678
A37: 16 | B37: 16 | C37: Зарипова 13Б | D37: 3 | E37: http://178.207.13.207 | F37: Альмет | G37: Шарифуллин Динар Ильфирович кв.44, 8(917)220-66-29 | H37: Таттелеком | I37: 102032812 | J37: Спутник, Камеры | K37: 25 числа | L37: 590 | M37: 590 | N37: 46009 | O37: 590 | P37: 45980 | Q37: 590 | R37: 45947 | S37: 590 | T37: 45919 | U37: 590 | V37: 590 | W37: 590 | X37: 45861 | Y37: 569 | Z37: 45827 | AA37: 569 | AB37: 45797 | AC37: 569 | AD37: 45763 | AE37: 569 | AF37: 45735 | AG37: 569 | AH37: 45706 | AI37: 569 | AJ37: 45678
A38: 17 | B38: 17 | C38: Зарипова 13А | D38: 2 | E38: http://78.138.190.10:80 | F38: Альмет | G38: Асафов Виктор Андреевич, 89871752101 кв 38 | H38: Таттелеком | I38: 105556984 | J38: Спутник, Камеры | K38: 25 числа | L38: 600 | M38: 600 | N38: 46009 | O38: 600 | P38: 45980 | Q38: 600 | R38: 45947 | S38: 600 | T38: 45919 | U38: 600 | V38: 600 | W38: 600 | X38: 45861 | Y38: 600 | Z38: 45827 | AA38: 600 | AB38: 45797 | AC38: 600 | AD38: 45763 | AE38: 600 | AF38: 45735 | AG38: 600 | AH38: 45706 | AI38: 600 | AJ38: 45678
A39: 18 | B39: 18 | C39: Зарипова 17 | D39: 2 | E39: http://178.207.67.192/ | F39: Альмет | G39: Мухаматов Ильгиз Илгизарович. | H39: Таттелеком | I39: 101 715 440 | J39: Спутник | K39: 25 числа | L39: 490 | M39: 490 | N39: 46009 | O39: 490 | P39: 45980 | Q39: 490 | R39: 45947 | S39: 490 | T39: 45919 | U39: 490 | V39: 490 | W39: 490 | X39: 45861 | Y39: 490 | Z39: 45827 | AA39: 490 | AB39: 45797 | AC39: 490 | AD39: 45763 | AE39: 490 | AF39: 45735 | AG39: 490 | AH39: 45706 | AI39: 490 | AJ39: 45678
A40: 18 | B40: 18 | C40: Зарипова 21 | D40: 5 | E40: http://217.173.17.188:8080 | F40: Альмет | G40: Нурдиллаев Рамиль Равилевич кв.43, 8(917)859-10-55 | H40: МТС | I40: 31039260179 | J40: Спутник, Камеры | K40: до 25 числа | L40: 450р. | M40: 450 | N40: 46009 | O40: 450 | P40: 45980 | Q40: 450 | R40: 45947 | S40: 450 | T40: 45919 | U40: 450 | V40: 450 | W40: 450 | X40: 45861 | Y40: 450 | Z40: 45827 | AA40: 450 | AB40: 45797 | AC40: 450 | AD40: 45764 | AE40: 450 | AF40: 45735 | AG40: 450 | AH40: 45706 | AI40: 450 | AJ40: 45678
...

Sheet Зеленодольск
Q1: оплата в октябре | S1: оплата в сентябре | U1: оплата в августе | W1: оплата в июле | Y1: оплата в июне | AA1: оплата в мае | AC1: оплата в апреле | AE1: оплата в марте | AG1: оплата в феврале | AI1: оплата в январе
A2: Дата начало обслу-ания | C2: Адреса и где находится шкаф в примечании | D2: Кол-во подъездов | E2: Ссылки на роутер | F2: УК | G2: ФИО | H2: Оператор | I2: Договор, логин и пароль в примечании | J2: Что установлено | K2: Дата списания | L2: Тариф | M2: оплата в декабре | O2: оплата в ноябре | Q2: сумма | R2: дата | S2: сумма | T2: дата | U2: сумма | V2: дата | W2: сумма | X2: дата | Y2: сумма | Z2: дата | AA2: сумма | AB2: дата | AC2: сумма | AD2: дата | AE2: сумма | AF2: дата | AG2: сумма | AH2: дата | AI2: сумма | AJ2: дата
A3: 44013 | B3: 1 | C3: К.Маркса д. 30а | D3: 1 | E3: http://178.205.102.182 нет статики | F3: Радужный | G3: Чукурова Надежда Григорьевна кв 1 89874050052 | H3: Таттелеком | I3: 100790035 | J3: Камеры | K3: 25 числа | L3: 730 | M3: 730 | N3: 46009 | O3: 730 | P3: 45980 | Q3: 730 | R3: 45947 | S3: 730 | T3: 45919 | U3: 730 | V3: 730 | W3: 730 | X3: 45861 | Y3: 730 | Z3: 45827 | AA3: 700 | AB3: 45797 | AC3: 700 | AD3: 45763 | AE3: 700 | AF3: 45735 | AG3: 670 | AH3: 45706 | AI3: 670 | AJ3: 45678
A4: 44136 | B4: 2 | C4: К.Маркса д. 36а | D4: 1 | E4: https://marksa36a.keenetic.link | F4: Радужный | G4: Малиневская Светлана Эдуардовна кв 5, 89503264501 | H4: Таттелеком | I4: 106758698 | J4: Камеры | K4: 25 числа | L4: 550 | M4: 550 | N4: 46009 | O4: 550 | P4: 45980 | Q4: 550 | R4: 45947 | S4: 550 | T4: 45919 | U4: 550 | V4: 550 | W4: 550 | X4: 45861 | Y4: 550 | Z4: 45827 | AA4: 550 | AB4: 45797 | AC4: 550 | AD4: 45763 | AE4: 550 | AF4: 45735 | AG4: 550 | AH4: 45706 | AI4: 550 | AJ4: 45678
A5: 44136 | B5: 3 | C5: К.Маркса д. 36б | D5: 1 | E5: https://marksa36b.keenetic.link/ | F5: Радужный | G5: Мухаев Юрий Леонидович 89053100058 кв 9 | H5: Таттелеком | I5: 100896498 | J5: Камеры | K5: 25 числа | L5: 500 | M5: 500 | N5: 46009 | O5: 500 | P5: 45980 | Q5: 500 | R5: 45947 | S5: 500 | T5: 45919 | U5: 500 | V5: 500 | W5: 500 | X5: 45861 | Y5: 500 | Z5: 45827 | AA5: 500 | AB5: 45797 | AC5: 500 | AD5: 45763 | AE5: 500 | AF5: 45735 | AG5: 550 | AH5: 45706 | AI5: 500 | AJ5: 45678
A6: 45200 | B6: 4 | C6: Комарова д. 14а | D6: 4 | F6: ТСЖ №6 | G6: Христафоров Сергей Васильевич, 89600387171 | H6: ТатаисНефть | I6: 1364654 | J6: Спутники | K6: 25 числа | L6: 502 | M6: 502 | N6: 46009 | O6: 502 | P6: 27.22.25 | Q6: 502 | R6: 45947 | S6: 502 | T6: 45919 | U6: 502 | V6: 502 | W6: 502 | X6: 45861 | Y6: 502 | Z6: 45826 | AA6: 502 | AB6: 45797 | AC6: 502 | AD6: 45763 | AE6: 502 | AF6: 45735 | AG6: 502 | AH6: 45706 | AI6: 502 | AJ6: 45678
C7: Ленина д. 21 | D7: 4 | F7: Жилкомплекс | G7: Якупов Марат Мансурович | H7: Yota | I7: 6063194562 | J7: Спутники | K7: 4 числа
C8: Ленина д. 21 | D8: 4 | F8: Жилкомплекс | G8: Егорова Татьяна Алексеевна, кв 14 | H8: Таттелеком | I8: 105 805 637 | J8: Спутники | K8: 19 числа | L8: 550 | M8: 550 | N8: 46009 | O8: 550 | P8: 45980 | Q8: 550 | R8: 45947 | S8: 550 | T8: 45919 | U8: 550 | V8: 550 | W8: 550 | X8: 45859 | Y8: 550 | Z8: 45827 | AA8: 550 | AB8: 45796 | AC8: 500 | AD8: 45763 | AE8: 500 | AF8: 45735 | AG8: 500 | AH8: 45706 | AI8: 500 | AJ8: 45678
A9: 44348 | B9: 5 | C9: Гоголя д. 22 а | D9: 2 | F9: Жилкомплекс | G9: Сектор безопасности | H9: Оникс | I9: 16966-06-2021 | J9: Спутники | K9: 1 числа | L9: без.нал
A10: 44348 | B10: 6 | C10: Карла Маркса д. 35 | D10: 1 | F10: Жилкомплекс | G10: Сектор безопасности | H10: Оникс | I10: 16966-06-2021 | J10: Спутники | K10: 1 числа | L10: без.нал
A11: 44348 | B11: 7 | C11: Ленина д. 1 | D11: 2 | F11: Жилкомплекс | G11: Сектор безопасности | H11: Оникс | I11: 16966-06-2021 | J11: Спутники | K11: 1 числа | L11: без.нал
A12: 44348 | B12: 8 | C12: Ленина д. 2 | D12: 1 | F12: Жилкомплекс | G12: Сектор безопасности | H12: Оникс | I12: 16966-06-2021 | J12: Спутники | K12: 1 числа | L12: без.нал
A13: 44378 | B13: 9 | C13: Паратская д. 13 | D13: 3 | F13: Жилкомплекс | G13: Сектор безопасности | H13: Оникс | I13: 16966-06-2021 | J13: Спутники | K13: 1 числа | L13: без.нал
A14: 44378 | B14: 10 | C14: Паратская д. 15 | D14: 3 | F14: Жилкомплекс | G14: Сектор безопасности | H14: Оникс | I14: 16966-06-2021 | J14: Спутники | K14: 1 числа | L14: без.нал
A15: 44348 | B15: 11 | C15: Тукая д. 22 | D15: 1 | F15: Жилкомплекс | G15: Сектор безопасности | H15: Оникс | I15: 16966-06-2021 | J15: Спутники | K15: 1 числа | L15: без.нал
A16: 45383 | B16: 12 | C16: Карла Маркса д. 57а | D16: 1 | E16: karlamarksa57a.keenetic.link | F16: Жилкомплекс | G16: Сектор безопасности | H16: Оникс | I16: 16966-06-2021 | J16: Спутники | K16: 1 числа | L16: без.нал
A17: 45352 | B17: 13 | C17: Комарова д. 21 | D17: 4 | E17: komarova21.keenetic.link | F17: Жилкомплекс | G17: Сектор безопасности | H17: Оникс | I17: 16966-06-2021 | J17: Спутники | K17: 1 числа | L17: без.нал
A18: 45352 | B18: 14 | C18: Комарова д. 23 | D18: 5 | E18: komarova23.keenetic.name | F18: Жилкомплекс | G18: Сектор безопасности | H18: Оникс | I18: 16966-06-2021 | J18: Спутники | K18: 1 числа | L18: без.нал
A19: 45352 | B19: 15 | C19: Королева д. 10 | D19: 4 | F19: Жилкомплекс | G19: Сектор безопасности | H19: Оникс | I19: 16966-06-2021 | J19: Спутники | K19: 1 числа | L19: без.нал
A20: 45323 | B20: 16 | C20: Комарова д. 41 | D20: 3 | E20: https://inkey.rt.ru/main/domofons | G20: Система и платформа Ростелекома | H20: Ростелеком | J20: Спутники | L20: 0 | M20: 0 | O20: 0 | AA20: 0 | AC20: 0 | AE20: 0 | AG20: 0
A21: 45383 | B21: 17 | C21: Тургенева д. 54 | D21: 5 | E21: tyrgeneva54.keenetic.link | F21: Жилкомплекс | G21: Сектор безопасности | H21: Оникс | I21: 16966-06-2021 | J21: Спутники | K21: 1 числа | L21: без.нал
A22: 45413 | B22: 18 | C22: Комарова д. 27 | D22: 3 | E22: komarova27.keenetic.link | F22: Жилкомплекс | G22: Сектор безопасности | H22: Оникс | I22: 16966-06-2022 | J22: Спутники | K22: 1 числа | L22: без.нал
A23: 45444 | B23: 19 | C23: Комарова д. 37 | D23: 5 | E23: komarova37.keenetic.link | F23: Жилкомплекс | G23: Сектор безопасности | H23: Оникс | I23: 16966-06-2023 | J23: Спутники | K23: 1 числа | L23: без.нал
C24: Большая Заводская д. 75 | D24: 2 | F24: Жилкомплекс | G24: Сектор безопасности | H24: Yota | I24: Сафиуллин Раниф Рифхатович | J24: Спутники | K24: 22 числа | L24: 665 | M24: 665 | N24: 46009 | O24: 665 | P24: 45979 | Q24: 0 | S24: 0 | U24: 665 | V24: 665
C25: Комарова д. 39 | D25: 4 | F25: Жилкомплекс | G25: Сектор безопасности | H25: Оникс | I25: 16966-06-2024 | J25: Спутники | K25: 1 числа | L25: без.нал
C26: Гастелло д. 11 | D26: 2 | F26: Жилкомплекс | G26: Сектор безопасности | H26: Оникс | I26: 16966-06-2024 | J26: Спутники | K26: 1 числа | L26: без.нал
C27: Гастелло д. 7 | D27: 1 | F27: Жилкомплекс | G27: Сектор безопасности | H27: Оникс | I27: 16966-06-2024 | J27: Спутники | K27: 1 числа | L27: без.нал
C28: Гастелло д. 9 | D28: 2 | F28: Жилкомплекс | G28: Сектор безопасности | H28: Оникс | I28: 16966-06-2024 | J28: Спутники | K28: 1 числа | L28: без.нал
C29: Хазиева д. 5 | D29: 4 | F29: Жилкомплекс | G29: Сектор безопасности | H29: Оникс | I29: 16966-06-2024 | J29: Спутники | K29: 1 числа | L29: без.нал
B30: ИТОГО К ОПЛАТЕ | M30: =SUM(M3:M24) -> 3497 | O30: =SUM(O3:O24) -> 3497 | Q30: =SUM(Q3:Q8) -> 2832 | S30: =SUM(S3:S27) -> 2832 | U30: =SUM(U3:U27) -> 3497 | W30: =SUM(W3:W27) -> 2832 | Y30: =SUM(Y3:Y27) -> 2832 | AA30: =SUM(AA3:AA27) -> 2802 | AC30: =SUM(AC3:AC20) -> 2752 | AE30: =SUM(AE3:AE20) -> 2752 | AG30: =SUM(AG3:AG20) -> 2772 | AI30: =SUM(AI3:AI20) -> 2722
L34: Радужный | M34: =SUM(M3:M5) -> 1780 | O34: =SUM(O3:O5) -> 1780 | Q34: =SUM(Q3:Q5) -> 1780 | S34: =SUM(S3:S5) -> 1780 | U34: =SUM(U3:U5) -> 1780 | W34: =SUM(W3:W5) -> 1780 | Y34: =SUM(Y3:Y5) -> 1780 | AA34: =SUM(AA3:AA5) -> 1750 | AC34: =SUM(AC3:AC5) -> 1750 | AE34: =SUM(AE3:AE5) -> 1750 | AG34: =SUM(AG3:AG5) -> 1770 | AI34: =SUM(AI3:AI5) -> 1720 | AK34: =SUM(M34:AI34) -> 21200
L35: ТСЖ №6 | M35: =SUM(M6) -> 502 | O35: =SUM(O6) -> 502 | Q35: =SUM(Q6) -> 502 | S35: =SUM(S6) -> 502 | U35: =U6 -> 502 | W35: =W6 -> 502 | Y35: =Y6 -> 502 | AA35: =SUM(AA6) -> 502 | AC35: =AC6 -> 502 | AE35: =AE6 -> 502 | AG35: =AG6 -> 502 | AI35: =AI6 -> 502 | AK35: =SUM(M35:AI35) -> 6024
L36: Жилкомплекс | M36: =SUM(M8:M24) -> 1215 | O36: =SUM(O8:O24) -> 1215 | Q36: =SUM(Q8:Q24) -> 550 | S36: =SUM(S8) -> 550 | U36: =SUM(U8:U24) -> 1215 | W36: =W8 -> 550 | Y36: =Y8 -> 550 | AA36: =AA8 -> 550 | AC36: =AC8 -> 500 | AE36: =AE8 -> 500 | AG36: =AG8 -> 500 | AI36: =AI8 -> 500 | AK36: =SUM(M36:AI36) -> 8395
M37: =SUM(M34:M36) -> 3497 | O37: =SUM(O34:O36) -> 3497 | U37: =SUM(U34:U36) -> 3497

Sheet Казань
Q1: Оплата в октябре | S1: Оплата в сентябре | U1: Оплата в августе | W1: Оплата в июле | Y1: Оплата в июне | AA1: Оплата в мае | AC1: Оплата в апреле | AE1: Оплата в марте | AG1: Оплата в феврале | AI1: Оплата в январе
A2: Дата начало обслу-ания | C2: Адреса и где находится шкаф в примечании | D2: Кол-во подъездов | E2: Ссылки на роутер | F2: УК | G2: ФИО | H2: Оператор | I2: Договор, логин и пароль в примечании | J2: Что установлено | K2: Дата списания | L2: Тариф | M2: оплата в декабре | O2: оплата в ноябре | Q2: сумма | R2: дата | S2: сумма | T2: дата | U2: сумма | V2: дата | W2: сумма | X2: дата | Y2: сумма | Z2: дата | AA2: сумма | AB2: дата | AC2: сумма | AD2: дата | AE2: сумма | AF2: дата | AG2: сумма | AH2: дата | AI2: сумма | AJ2: дата
B3: 1 | C3: Сабан 1 кв 45 | D3: 3 | E3: http://92.255.198.107:8888 | F3: ЖКХ | G3: Назира апа ст.по дому | H3: Дом.ру | I3: 160007356203 | J3: Камеры | K3: 1 числа | L3: 930 | M3: 1010 | N3: 46010 | O3: 930 | P3: 45979 | Q3: 930 | R3: 45950 | S3: 930 | T3: 45919 | U3: 930 | V3: 930 | W3: 930 | X3: 45861 | Y3: 930 | Z3: 45826 | AA3: 930 | AB3: 45797 | AC3: 930 | AD3: 45763 | AE3: 800 | AF3: 45735 | AG3: 800 | AH3: 45706 | AI3: 800 | AJ3: 45678
C4: Хлебозаводская д 6 | H4: Таттелеком | I4: 102590785 | K4: до 5 числа | L4: 490 | M4: 490 | N4: 46009 | O4: 490 | P4: 45980 | Q4: 490 | R4: 45947 | S4: 490 | T4: 45919 | U4: 490 | V4: 490 | W4: 490 | X4: 45861
C5: Сабан 7а | D5: 2 | F5: ЖКХ | G5: Сафиуллин Раниф Рифхатович, 41 кв | H5: МТС | I5: 79876001969_serv1 - логин, g5i9m099 - пароль | J5: Камеры | L5: 835 | M5: 835 | N5: 46009 | O5: 835 | P5: 45979 | Q5: 700 | R5: 45947 | S5: 700 | T5: 45915 | U5: 700 | V5: 700 | W5: 640 | X5: 45861 | Y5: 640 | Z5: 45827 | AA5: 640 | AB5: 45797 | AC5: 640 | AD5: 45764 | AE5: 640 | AF5: 45735 | AG5: 640 | AH5: 45706 | AI5: 640 | AJ5: 45678
B6: 3 | C6: Кулахметова 25 к.1 57 кв | D6: 4 | E6: http://92.255.201.185:8889 | F6: ЖКХ | G6: Загидуллин Ренат Рафисович | H6: Дом.ру | I6: 160007613579 | J6: Камеры | K6: 1 числа | L6: 1115 | M6: 0 | Q6: 1115 | R6: 45950 | S6: 1115 | T6: 45919 | U6: 1115 | V6: 1115 | W6: 1115 | X6: 45861 | Y6: 1115 | Z6: 45826 | AA6: 1115 | AB6: 45797 | AC6: 1115 | AD6: 45763 | AE6: 955 | AF6: 45735 | AG6: 955 | AH6: 45706 | AI6: 955 | AJ6: 45678
C7: Кулахметова 22 | D7: 1 | F7: ЖКХ | G7: Нуриазов Рустем Рамилевич | H7: МТС | I7: 116 315 745 778 | J7: Камеры | K7: 5 число | L7: 525 | M7: 525 | N7: 46009 | O7: 525 | P7: 45979 | Q7: 525 | R7: 45947 | S7: 525 | T7: 45919 | U7: 525 | V7: 525 | W7: 525 | X7: 45861 | Y7: 525 | Z7: 45827 | AA7: 525 | AB7: 45797 | AC7: 525 | AD7: 45764 | AE7: 525 | AF7: 45735
B8: 4 | C8: Бакалейная 52А | D8: 1 | E8: http://89.251.157.129:8080 | F8: ЖКХ | G8: Загидуллин Ринат Рафисович кв.7 | H8: МТС | I8: 310 090 643 25 | J8: Камеры | K8: 15 числа | L8: 730 | M8: 730 | N8: 46009 | O8: 730 | P8: 45979 | Q8: 730 | R8: 45947 | S8: 730 | T8: 45919 | U8: 730 | V8: 730 | W8: 730 | X8: 45861 | Y8: 730 | Z8: 45826 | AA8: 730 | AB8: 45797 | AC8: 730 | AD8: 45763 | AE8: 730 | AF8: 45735 | AG8: 730 | AH8: 45707 | AI8: 650 | AJ8: 45678
B9: 5 | C9: Декабристов 106а (106б) | D9: 2 | E9: http://84.39.246.20 | F9: ЖКХ | G9: кв. 2, Шамгунов Олег (старший по дому) 89510646538 | H9: Казгорсеть (КГС) | I9: 5110116301 | J9: Камеры | K9: 15 числа | L9: 905 | M9: 905 | O9: 0 | Q9: 905 | S9: 905 | U9: 905 | W9: 905 | Y9: 875 | Z9: 45848 | AA9: 875 | AB9: 45818 | AC9: 875 | AD9: 45763 | AE9: 875 | AF9: 45735 | AG9: =875+875 -> 1750 | AH9: 45726 | AI9: 875 | AJ9: 45667
B10: 6 | C10: Ютазинская 16 | D10: 1 | E10: http://87.117.180.31 | F10: ЖКХ | G10: Фатыхов Рустам Рустемович | H10: Ростелеком | I10: 316 020 075 006 | J10: Камеры | K10: ежедневно равными долями | L10: 279 | M10: 826 | N10: 46009 | O10: 279 | P10: 45979 | Q10: 279 | R10: 45947 | S10: 279 | T10: 45919 | U10: 279 | V10: 279 | W10: 279 | X10: 45861 | Y10: 279 | Z10: 45826 | AA10: 279 | AB10: 45797 | AC10: 0 | AE10: 279 | AF10: 45735 | AG10: 276 | AH10: 45707 | AI10: 276 | AJ10: 45678
B11: 7 | C11: Кулахметова 17 к 3 под 3 | D11: 1 | E11: https://kulax17k3p3.keenetic.name/controlPanel/devicesList | F11: ЖКХ | G11: Якупов Марат | H11: Yota | I11: 6063194562 | J11: Камеры | K11: 23 числа | L11: 665 | M11: 665 | N11: 46009 | O11: 665 | P11: 45979 | Q11: 665 | R11: 45947 | S11: =665+665 -> 1330 | T11: 45919 | U11: 665 | V11: 45889 | W11: 665 | X11: 45856 | Y11: 665 | Z11: 45826 | AA11: 550 | AB11: 45797 | AC11: 550 | AD11: 45763 | AE11: 550 | AF11: 45735 | AG11: 550 | AH11: 45707 | AI11: 550 | AJ11: 45678
B12: 8 | C12: Серова 4,кв. 38 | D12: 4 | E12: https://dekab106.keenetic.link/controlPanel/devicesList | F12: ЖКХ | G12: Сафиуллин Раниф Рифхатович | H12: МТС | I12: 31009554936 | J12: Камеры | L12: 750 | M12: 750 | N12: 46009 | O12: 750 | P12: 45979 | Q12: 750 | R12: 45947 | S12: 750 | T12: 45919 | U12: 750 | V12: 750 | W12: 750 | X12: 45861 | Y12: 750 | Z12: 45827 | AA12: 750 | AB12: 45797 | AC12: 750 | AD12: 45764 | AE12: 740 | AF12: 45735 | AG12: 740 | AH12: 45706 | AI12: 740 | AJ12: 45678
B13: 9 | C13: Декабристов 178А | D13: 6 | E13: http://89.251.144.64:8080/controlPanel/devicesList | F13: ЖКХ | G13: Сафиуллин Раниф Рифхатович | H13: МТС | I13: 917 276 5969 | J13: Спутник, Камеры | K13: 18 числа | L13: 910 | M13: 910 | O13: 910 | Q13: 910 | R13: 45947 | S13: 910 | U13: 910 | W13: 840 | Y13: 840 | Z13: 45855 | AA13: 1680 | AB13: 45825 | AC13: 840 | AD13: 45764 | AE13: 840 | AF13: 45918 | AG13: 840 | AH13: 45706 | AI13: 840 | AJ13: 45673
C14: Декабристов 127 | D14: 4 | F14: ЖКХ | G14: Фомичев Владимир Акимович 130 кв 89046678189 | H14: Тателеком | I14: 96185 | J14: Камеры | L14: 518 | M14: 518 | N14: 46009 | O14: 518
B15: 11 | C15: Горьковское Шоссе 17 | D15: 3 | F15: Радужный | G15: Коновалова Ольга Владимировна, кв 37, 89274174715 | H15: Тателеком | I15: 103460112 | J15: Спутник | K15: 25 числа | L15: 530 | M15: 530 | N15: 46009 | O15: 530 | P15: 45980 | Q15: 500 | R15: 45947 | S15: 500 | T15: 45919 | U15: 500 | V15: 500 | W15: 500 | X15: 45861 | Y15: 500 | Z15: 45827 | AA15: 500 | AB15: 45797 | AC15: 500 | AD15: 45763 | AE15: 550 | AF15: 45735 | AG15: 500 | AH15: 46009 | AI15: 500 | AJ15: 45678
B16: 10 | C16: Зур Урам 1 к 4 | D16: 18 | F16: Радужный | G16: Интернет оплачивает УК | J16: Спутник | M16: 0 | O16: 0 | Q16: 0 | S16: 0 | U16: 0 | V16: 0 | W16: 0 | Y16: 0 | AA16: 0 | AC16: 0 | AE16: 0 | AG16: 0
B17: ИТОГО К ОПЛАТЕ | M17: =SUM(M3:M15) -> 8694 | O17: =SUM(O3:O15) -> 7162 | Q17: =SUM(Q3:Q15) -> 8499 | S17: =SUM(S3:S15) -> 9164 | U17: =SUM(U3:U15) -> 8499 | W17: =SUM(W3:W15) -> 8369 | Y17: =SUM(Y3:Y15) -> 7849 | AA17: =SUM(AA3:AA15) -> 8574 | AC17: =SUM(AC3:AC15) -> 7455 | AE17: =SUM(AE3:AE15) -> 7484 | AG17: =SUM(AG3:AG15) -> 7781 | AI17: =SUM(AI3:AI15) -> 6826
L20: ЖКХ | M20: =SUM(M3:M14) -> 8164 | O20: =SUM(O3:O14) -> 6632 | Q20: =SUM(Q3:Q14) -> 7999 | S20: =SUM(S3:S14) -> 8664 | U20: =SUM(U3:U14) -> 7999 | W20: =SUM(W3:W14) -> 7869 | Y20: =SUM(Y3:Y14) -> 7349 | AA20: =SUM(AA3:AA14) -> 8074 | AC20: =SUM(AC3:AC14) -> 6955 | AE20: =SUM(AE3:AE14) -> 6934 | AG20: =SUM(AG3:AG14) -> 7281 | AI20: =SUM(AI3:AI14) -> 6326 | AK20: =SUM(M20:AJ20) -> 90246
L21: Радужный | M21: =SUM(M15:M16) -> 530 | O21: =O15 -> 530 | Q21: =Q15 -> 500 | S21: =S15 -> 500 | U21: =U15 -> 500 | W21: =SUM(W15) -> 500 | Y21: =SUM(Y15) -> 500 | AA21: =SUM(AA15) -> 500 | AC21: =AC15 -> 500 | AE21: =SUM(AE15) -> 550 | AG21: =AG15 -> 500 | AI21: =AI15 -> 500 | AK21: =SUM(M21:AJ21) -> 6110

Sheet Иннополис
B1: Дата начало обслу-ания | D1: Адреса и где находится шкаф в примечании | E1: Кол-во подъездов | F1: Ссылки на роутер | G1: УК | H1: ФИО | I1: Оператор | J1: Договор, логин и пароль в примечании | K1: Что установлено | L1: Дата списания | M1: Тариф | N1: оплата в декабре | P1: оплата в ноябре | R1: оплата в октябре | T1: оплата в сентяборе | V1: оплата в августе | X1: оплата в июле | Z1: оплата в июне | AB1: оплата в маи | AD1: оплата в апреле | AF1: оплата в марте | AH1: оплата за феврале | AJ1: оплата за январь
A2: 1 | B2: 44835 | C2: 1 | D2: Спортивная 114 Домофон Спутник | E2: 3 | G2: иннофонд | H2: Якупов Марат Мансурович | I2: Yota | J2: 6063194562 | K2: Спутник | L2: 21 числа | M2: 665 | N2: 0 | P2: 0 | R2: 665 | S2: 45947 | T2: 665 | U2: 45919 | V2: 665 | W2: 45889 | X2: 665 | Y2: 45861 | Z2: 665 | AA2: 45826 | AB2: 665 | AC2: 45797 | AD2: 550 | AE2: 45763 | AF2: 550 | AG2: 45735 | AH2: 550 | AI2: 45706 | AJ2: 550 | AK2: 45673
A3: 1 | B3: 45017 | C3: 2 | D3: Спортивная 106 Домофон Спутник | E3: 1 | G3: иннофонд | H3: Якупов Марат Мансурович | I3: Yota | J3: 6063194562 | K3: Спутник | L3: 20 числа | M3: 665 | N3: 665 | O3: 46009 | P3: 665 | Q3: 45979 | R3: 665 | S3: 45947 | T3: 665 | U3: 45919 | V3: 665 | W3: 45889 | X3: 665 | Y3: 45861 | Z3: 1330 | AA3: 45826 | AB3: 665 | AC3: 45797 | AD3: 550 | AE3: 45763 | AF3: 1100 | AG3: 45735 | AH3: 550 | AI3: 45706 | AJ3: 550 | AK3: 45673
C4: ИТОГО К ОПЛАТЕ | M4: =SUM(M2:M3) -> 1330 | N4: =SUM(N2:N3) -> 665 | P4: =SUM(P2:P3) -> 665 | R4: =SUM(R2:R3) -> 1330 | T4: =SUM(T2:T3) -> 1330 | V4: =SUM(V2:V3) -> 1330 | X4: =SUM(X2:X3) -> 1330 | Z4: =SUM(Z2:Z3) -> 1995 | AB4: =SUM(AB2:AB3) -> 1330 | AD4: =SUM(AD2:AD3) -> 1100 | AF4: =SUM(AF2:AF3) -> 1650 | AH4: =SUM(AH2:AH3) -> 1100 | AJ4: =SUM(AJ2:AJ3) -> 1100 | AL4: =SUM(N4:AJ4) -> 14925

Sheet Тюмень
A1: Дата начало обслу-ания | B1: Нумерация | C1: Адреса и где находится шкаф в примечании | E1: Кол-во подъездов | F1: Ссылки на роутер | G1: УК | H1: ФИО | I1: Оператор | J1: Договор, логин и пароль в примечании | K1: Что установлено | L1: Дата списания | M1: Тариф | N1: оплата в декабре | P1: оплата в ноябре | R1: оплата в октябре | T1: оплата в сентябре | V1: оплата в августе | X1: оплата в июле | Z1: оплата в июне | AB1: оплата в мае | AD1: оплата в АПРЕЛЬ | AF1: оплата в марте | AH1: оплата в феврале | AJ1: оплата в январе
A2: 43742 | B2: 65 | C2: Республики д. 181 | E2: 1 | F2: http://188.186.176.220/ | G2: жсу | H2: Безопасный город | I2: Дом.ру | J2: ФК 5610 | K2: Спутник | L2: 10 числа | M2: без.нал | AB2: 0 | AE2: 45392
A3: 43913 | B3: 67 | C3: Рижская д. 80 | E3: 4 | F3: http://92.255.171.20:8888 | G3: жсу | H3: Безопасный город | I3: Дом.ру | J3: ФК 5610 | K3: Спутник | L3: 10 числа | M3: без.нал | AB3: 0 | AE3: 45392
A4: 43255 | B4: 63 | C4: 50 Лет Октября д. 60 | D4: 2 | E4: 4 | G4: жсу | H4: Колова Юлия | I4: МТС | J4: 8 982 937 9006 | K4: Спутник | M4: 600 | N4: 600 | O4: 46009 | P4: 600 | Q4: 45979 | R4: 600 | S4: 45950 | T4: 600 | U4: 45919 | V4: 600 | W4: 600 | X4: 600 | Y4: 45861
A5: 43266 | B5: 64 | C5: 50 лет Октября д. 68 | D5: 3 | E5: 2 | G5: жсу | H5: Колова Юлия | I5: МТС | J5: 8 982 947 6256 | K5: Спутник | M5: 600 | N5: 600 | O5: 46009 | P5: 600 | Q5: 45979 | R5: 600 | S5: 45950 | T5: 600 | U5: 45919 | V5: 600 | W5: 600 | X5: 600 | Y5: 45861
A6: 45611 | C6: Республики д. 183 | D6: 19 | E6: 1 | F6: http://109.194.162.243 | G6: жсу | H6: Колова Юлия | I6: Дом.ру | J6: 720017283753 | K6: Спутник, камеры | M6: =800+200 -> 1000 | N6: 1140 | O6: 46010 | P6: 1000.01 | Q6: 45980 | R6: 1000 | S6: 45950 | T6: 1000 | U6: 45919 | V6: 1000 | W6: 1000 | X6: 1000 | Y6: 45861 | Z6: 1000 | AA6: 45826 | AB6: 1000 | AC6: 45797 | AD6: 1000 | AE6: 45763 | AF6: 1000 | AG6: 45735 | AH6: 800 | AI6: 45706 | AJ6: 800 | AK6: 45678
C7: Севастопольская , 25 кв 46 | D7: 20 | G7: жсу | H7: Колова Юлия | I7: Дом.ру | J7: 720018904822 | K7: Спутник | M7: 950 | N7: 950 | O7: 46010 | P7: 950 | Q7: 45980
A8: 43264 | B8: 57 | C8: Севастопольская , 33 , 33 | D8: 21 | E8: 3 | F8: статики нет | G8: жсу | H8: Сафиуллин Раниф | I8: Ростелеком | J8: 572011585088 | K8: Спутник | L8: 21 числа | M8: 689 | N8: 689 | O8: 46009 | P8: 689 | Q8: 45979 | R8: 689 | S8: 45947 | T8: 689 | U8: 45919 | V8: 689 | W8: 689 | X8: 689 | Y8: 45856 | Z8: 689 | AA8: 45826 | AB8: 689 | AC8: 45797 | AD8: 689 | AE8: 45793 | AF8: 689 | AG8: 45735 | AH8: 689 | AI8: 45706 | AJ8: 649 | AK8: 45677
A9: 44542 | B9: 60 | C9: Текстильная д.1 | D9: 22 | F9: Симка йота Алкател | G9: жсу | H9: Якупов Марат | I9: Yota | J9: 6063194562 | K9: Спутник | L9: 22 числа | M9: 665 | N9: 1330 | O9: 46009 | P9: 665 | Q9: 45979 | R9: 665 | S9: 45947 | T9: 665 | U9: 45919 | V9: 0 | W9: 0 | X9: 665 | Y9: 45856 | Z9: 665 | AA9: 45826 | AB9: 550 | AC9: 45797 | AD9: 550 | AE9: 45763 | AF9: 550 | AG9: 45735 | AH9: 550 | AI9: 45707 | AJ9: 550 | AK9: 45682
A10: 44519 | B10: 62 | C10: Текстильная д.5 | D10: 23 | F10: Симка йота Алкател | G10: жсу | H10: Якупов Марат | I10: Yota | J10: 6063194562 | K10: Спутник | L10: 21 числа | M10: 725 | R10: 725 | S10: 45947 | T10: 725 | U10: 45919 | V10: 725 | W10: 45889 | X10: 725 | Y10: 45861 | Z10: 725 | AA10: 45826 | AB10: 725 | AC10: 45797 | AD10: 600 | AE10: 45763 | AF10: 600 | AG10: 45735 | AH10: 600 | AJ10: 600 | AK10: 45673
A11: 44519 | C11: Текстильная д.5, 23 кв | D11: 24 | E11: 4 | G11: жсу | H11: Лобанова Анна | I11: Дом.ру | J11: 720018899016 | K11: Спутник | M11: 950 | N11: 951 | O11: 46010 | P11: 950 | Q11: 45980
A12: 45354 | B12: 59 | C12: Одесская д. 51, кв 36, 89044968823 | D12: 26 | F12: Стоит рег, без статики | G12: жсу | H12: Акмалов Игорь Русланович | I12: Билайн | J12: 0 858 024 535 | K12: Спутник | L12: 20 числа | M12: 955 | N12: 955 | P12: 955 | Q12: 45979 | R12: 955 | S12: 45950 | T12: 955 | U12: 45920 | V12: 955 | W12: 45889 | X12: 955 | Y12: 45858 | Z12: 955 | AA12: 45828 | AB12: 955 | AC12: 45797 | AD12: 955 | AE12: 45763 | AF12: 840 | AG12: 45736 | AH12: 840 | AI12: 45708 | AJ12: 840 | AK12: 45678
A13: 45181 | B13: 55 | C13: Пермякова д. 16 кв 23 | D13: 27 | G13: жсу | H13: Сафиуллин Раниф | I13: Ростелеком | J13: 572011580518 | K13: Спутник | L13: 21 числа | M13: 695 | N13: 695 | O13: 46009 | P13: 695 | Q13: 45979 | R13: 695 | S13: 45947 | T13: 695 | U13: 45919 | V13: 695 | W13: 695 | X13: 695 | Y13: 45856 | Z13: 695 | AA13: 45826 | AB13: 695 | AC13: 45797 | AD13: 695 | AE13: 45793 | AF13: 695 | AG13: 45735 | AH13: 695 | AI13: 45706 | AJ13: 655 | AK13: 45677
A14: 43817 | C14: Пермякова д. 24 | D14: 28 | E14: 5 | F14: http://109.68.171.185:81 | G14: жсу | H14: Сафиуллин Раниф | I14: Ростелеком | J14: 572 011 701 159 | K14: Спутник | M14: 774 | N14: 774 | O14: 46009 | P14: 774 | Q14: 45979 | R14: 774 | S14: 45947 | T14: 774 | U14: 45919 | V14: 774 | W14: 774 | X14: 504 | Y14: 45856 | Z14: 474 | AA14: 45826 | AB14: 474 | AC14: 45797 | AD14: 16.93 | AE14: 45793 | AH14: 624 | AI14: 45715
A15: 43262 | B15: 58 | C15: Севастопольская, 25 | E15: 4 | F15: http://188.186.176.222:80 | G15: жсу | H15: Безопасный город | I15: Дом.ру | J15: ФК 5610 | K15: Спутник | L15: 10 числа | M15: без.нал | AB15: 0 | AE15: 45392
A16: 45444 | B16: 71 | C16: 30 Лет Победы д. 73 | D16: 1 | G16: ЖЭУ 9 | H16: Лобанова Анна | I16: Дом.ру | J16: 720016524626 | K16: Спутник | L16: 1 числа | M16: 700 | N16: 700 | O16: 46010 | P16: 700 | Q16: 45980 | R16: 700 | S16: 45950 | T16: 700 | U16: 45919 | V16: 700 | W16: 700 | X16: 700 | Y16: 45861 | Z16: 700 | AA16: 45826 | AB16: 700 | AC16: 45797 | AD16: 700 | AE16: 45763 | AF16: 850 | AG16: 45735 | AH16: 700 | AI16: 45706 | AJ16: 700 | AK16: 45678
C17: Ткацкий 18 | D17: 51 | E17: 8 | G17: Жэу 9 | H17: Колова Юлия | I17: Ростелеком | J17: 572 011 720 288 | K17: Спутники | M17: 669 | N17: 669 | O17: 46010 | P17: 399 | Q17: 45979 | R17: 399 | S17: 45950 | T17: 322 | U17: 45919 | V17: 0 | W17: 0 | X17: 0
A18: 43840 | B18: 40 | C18: Ростовцева д. 23 | E18: 1 | F18: Кинетик поставить | G18: Суходолье | H18: Безопасный город | I18: Позитив | J18: 00-0655 | K18: Спутник | L18: 1 числа | M18: без.нал | AB18: 0 | AE18: 45407
A19: 44004 | B19: 42 | C19: Ростовцева д. 25 | E19: 1 | F19: rostovtseva25.keenetic.link | G19: Суходолье | H19: Безопасный город | I19: Позитив | J19: 00-0655 | K19: Спутник | L19: 1 числа | M19: без.нал | AB19: 0 | AE19: 45407
A20: 44000 | B20: 41 | C20: Ростовцева д. 25 К 1 | E20: 1 | F20: rostovtseva25k1.keenetic.link | G20: Суходолье | H20: Безопасный город | I20: Позитив | J20: 00-0655 | K20: Спутник | L20: 1 числа | M20: без.нал | AB20: 0 | AE20: 45407
A21: 44230 | B21: 44 | C21: Ростовцева д. 27 К 1 | E21: 1 | F21: Кинетик поставить | G21: Суходолье | H21: Безопасный город | I21: Позитив | J21: 00-0655 | K21: Спутник | L21: 1 числа | M21: без.нал | AB21: 0 | AE21: 45407
A22: 44335 | B22: 43 | C22: Ростовцева д. 27 К 2 | E22: 1 | F22: Кинетик поставить | G22: Суходолье | H22: Безопасный город | I22: Позитив | J22: 00-0655 | K22: Спутник | L22: 1 числа | M22: без.нал | AB22: 0 | AE22: 45407
A23: 43816 | B23: 32 | C23: Б. Житкова д. 10 | E23: 1 | F23: Кинетик постаивить | G23: Суходолье | H23: Безопасный город | I23: Позитив | J23: 00-0655 | K23: Спутник | L23: 1 числа | M23: без.нал | AB23: 0 | AE23: 45407
A24: 43908 | B24: 22 | C24: Б. Житкова д. 2 | E24: 1 | F24: Кинетик постаивить | G24: Суходолье | H24: Безопасный город | I24: Позитив | J24: 00-0655 | K24: Спутник | L24: 1 числа | M24: без.нал | AB24: 0 | AE24: 45407
B25: 23 | C25: Б. Житкова д. 4 | E25: 1 | F25: zhitkova4.keenetic.link | G25: Суходолье | H25: Безопасный город | I25: Позитив | J25: 00-0655 | K25: Спутник | L25: 1 числа | M25: без.нал | AB25: 0 | AE25: 45407
A26: 43301 | B26: 24 | C26: Б. Житкова д. 5 | E26: 1 | F26: zhitkova5.keenetic.link | G26: Суходолье | H26: Безопасный город | I26: Позитив | J26: 00-0655 | K26: Спутник | L26: 1 числа | M26: без.нал | AB26: 0 | AE26: 45407
A27: 43297 | B27: 25 | C27: Б. Житкова д. 5 К 1 | E27: 1 | F27: zhitkova5k1.keenetic.link | G27: Суходолье | H27: Безопасный город | I27: Позитив | J27: 00-0655 | K27: Спутник | L27: 1 числа | M27: без.нал | AB27: 0 | AE27: 45407
A28: 45209 | B28: 27 | C28: Б. Житкова д. 6 | E28: 1 | F28: zhitkova6.keenetic.link | G28: Суходолье | H28: Безопасный город | I28: Позитив | J28: 00-0655 | K28: Спутник | L28: 1 числа | M28: без.нал | AB28: 0 | AE28: 45407
A29: 45111 | B29: 26 | C29: Б. Житкова д. 6 К 1 | E29: 1 | F29: zhitkova6k1.keenetic.link | G29: Суходолье | H29: Безопасный город | I29: Позитив | J29: 00-0655 | K29: Спутник | L29: 1 числа | M29: без.нал | AB29: 0 | AE29: 45407
A30: 43304 | B30: 28 | C30: Б. Житкова д. 7 | E30: 1 | F30: zhitkova7.keenetic.link | G30: Суходолье | H30: Безопасный город | I30: Позитив | J30: 00-0655 | K30: Спутник | L30: 1 числа | M30: без.нал | AB30: 0 | AE30: 45407
A31: 43294 | B31: 29 | C31: Б. Житкова д. 7 К 1 | E31: 1 | F31: zhitkova7k1.keenetic.link | G31: Суходолье | H31: Безопасный город | I31: Позитив | J31: 00-0655 | K31: Спутник | L31: 1 числа | M31: без.нал | AB31: 0 | AE31: 45407
A32: 44915 | B32: 30 | C32: Б. Житкова д. 8 | E32: 1 | F32: zhitkova8.keenetic.link | G32: Суходолье | H32: Безопасный город | I32: Позитив | J32: 00-0655 | K32: Спутник | L32: 1 числа | M32: без.нал | AB32: 0 | AE32: 45407
A33: 44230 | B33: 31 | C33: Б. Житкова д. 8 К 1 | E33: 1 | F33: Кинетик постаивить | G33: Суходолье | H33: Безопасный город | I33: Позитив | J33: 00-0655 | K33: Спутник | L33: 1 числа | M33: без.нал | AB33: 0 | AE33: 45407
A34: 43727 | B34: 33 | C34: Монтажников д. 43 | E34: 1 | F34: montazhnikov43.keenetic.link | G34: Суходолье | H34: Безопасный город | I34: Позитив | J34: 00-0655 | K34: Спутник | L34: 1 числа | M34: без.нал | AB34: 0 | AE34: 45407
A35: 43769 | B35: 34 | C35: Монтажников д. 45 | E35: 1 | F35: montazhnikov45.keenetic.link | G35: Суходолье | H35: Безопасный город | I35: Позитив | J35: 00-0655 | K35: Спутник | L35: 1 числа | M35: без.нал | AB35: 0 | AE35: 45407
A36: 43768 | B36: 35 | C36: Монтажников д. 47 | E36: 1 | F36: montazhnikov47.keenetic.link | G36: Суходолье | H36: Безопасный город | I36: Позитив | J36: 00-0655 | K36: Спутник | L36: 1 числа | M36: без.нал | AB36: 0 | AE36: 45407
A37: 43969 | B37: 36 | C37: Монтажников д. 49 | E37: 1 | F37: montazhnikov49.keenetic.link | G37: Суходолье | H37: Безопасный город | I37: Позитив | J37: 00-0655 | K37: Спутник | L37: 1 числа | M37: без.нал | AB37: 0 | AE37: 45407
... A40: 43711 | B40: 39 | C40: Монтажников д. 55 | E40: 1 | F40: Кинетик поставить | G40: Суходолье | H40: Безопасный город | I40: Позитив | J40: 00-0655 | K40: Спутник | L40: 1 числа | M40: без.нал | AB40: 0 | AE40: 45407
A41: 45383 | B41: 51 | C41: Беляева д. 17 а | D41: 6 | E41: 3 | F41: Статика есть узнать в роутере | G41: На Пражской | H41: Сафиуллин Раниф | I41: Ростелеком | J41: 572011607853 | K41: Спутник | L41: 21 числа | M41: 774 | N41: 774 | O41: 46009 | P41: 774 | Q41: 45979 | R41: 774 | S41: 45947 | T41: 774 | U41: 45919 | V41: 774 | W41: 774 | X41: 774 | Y41: 45856 | Z41: 774 | AA41: 45826 | AB41: 774 | AC41: 45797 | AD41: 774 | AE41: 45793 | AF41: 774 | AG41: 45735 | AH41: 774 | AI41: 45706 | AJ41: 774 | AK41: 45677
A42: 45383 | B42: 50 | C42: Беляева д. 33 | D42: 7 | E42: 2 | F42: http://90.151.249.227:81/ | G42: На Пражской | H42: Сафиуллин Раниф | I42: Ростелеком | J42: 572011606169 | K42: Спутник | L42: 21 числа | M42: 705 | N42: 705 | O42: 46009 | P42: 705 | Q42: 45979 | R42: 705 | S42: 45947 | T42: 705 | U42: 45919 | V42: 705 | W42: 705 | X42: 705 | Y42: 45856 | Z42: 705 | AA42: 45826 | AB42: 705 | AC42: 45797 | AD42: 705 | AE42: 45793 | AF42: 705 | AG42: 45735 | AH42: 705 | AI42: 45706 | AJ42: 705 | AK42: 45677
...

Sheet Зион
A1: Дата начало обслу-ания | C1: Адреса и где находится шкаф в примечании | D1: Кол-во подъездов | E1: Ссылки на роутер | F1: УК | G1: ФИО | H1: Оператор | I1: Договор, логин и пароль в примечании | J1: Что установлено | K1: Дата списание абонетской платы | L1: Тариф | M1: оплата в январь | O1: оплата в декабре | Q1: оплата в ноябре | S1: оплата в октябре | U1: оплата в сентяборе | W1: оплата в августе | Y1: оплата в июле | AA1: оплата в июне | AC1: оплата в мае | AE1: оплата в апреле | AG1: оплата в марте | AI1: оплата за февраль | AK1: оплата за январь
B2: 1 | C2: Центральная 173 | F2: тринити | G2: Сафиуллин Раниф Рифхатович, дом 173 кв 4 | H2: Таттелеком | I2: 106 155 307 | J2: Камеры | K2: 25 числа | L2: 650 | O2: 650 | P2: 46009 | Q2: 650 | R2: 45980 | S2: 650 | T2: 45950 | U2: 650 | V2: 45919 | W2: 650 | X2: 650 | Y2: 650 | Z2: 45861 | AA2: 650 | AB2: 45827 | AC2: 650 | AD2: 45797 | AE2: 650 | AF2: 45763 | AG2: 650 | AH2: 45735 | AI2: 650 | AJ2: 45706 | AK2: 650 | AL2: 45678 | AX2: //
B3: 2 | C3: Зион -2 103 dom | F3: тринити | G3: Якупов Марат Мансурович | H3: Yota | I3: 6063194562 | J3: Камеры | L3: 665 | O3: 665 | P3: 46009 | Q3: 665 | R3: 45979 | S3: 665 | T3: 45947 | U3: 665 | V3: 45919 | W3: 665 | X3: 45889 | Y3: 665 | Z3: 45861 | AA3: 665 | AB3: 45826 | AC3: 665 | AD3: 45797 | AE3: 550 | AF3: 45763 | AG3: 550 | AH3: 45735 | AI3: 550 | AJ3: 45707 | AK3: 550 | AL3: 45678
B4: 3 | C4: 165 dom | F4: тринити | G4: Якупов Марат Мансурович | H4: Yota | I4: 6063194562 | J4: Камеры | K4: 26 числа | L4: 600 | P4: 46009 | W4: 0 | X4: 45889 | Y4: 1700 | Z4: 45856 | AA4: 850 | AB4: 45826 | AC4: 600 | AD4: 45797 | AE4: 600 | AF4: 45763 | AG4: 600 | AH4: 45735 | AI4: 600 | AJ4: 45707 | AK4: 600 | AL4: 45678
C5: ЖК Комфорт на столбе у въезда | F5: тринити | G5: Якупов Марат Мансурович | H5: Yota | I5: 6063194562 | J5: Камеры | K5: 19 числа | L5: 850 | O5: 850 | P5: 46009 | Q5: 850 | R5: 45979 | S5: 850 | T5: 45947 | U5: 850 | V5: 45919 | W5: 850 | X5: 45889 | Y5: 850 | Z5: 45861 | AA5: 850 | AB5: 45826 | AC5: 850 | AD5: 45797 | AE5: 1700 | AF5: 45763
B6: 4 | C6: 179 dom | F6: тринити | G6: Якупов Марат Мансурович | H6: Yota | I6: 6063194562 | J6: Камеры | K6: 13 числа | L6: 785 | O6: 0 | Q6: 0 | S6: 0 | U6: 0 | W6: 785 | X6: 45889 | Y6: 785 | Z6: 45861 | AA6: 785 | AB6: 45826 | AC6: 785 | AD6: 45797 | AE6: 650 | AF6: 45763 | AG6: 650 | AH6: 45735 | AI6: 650 | AJ6: 45707 | AK6: 650 | AL6: 45678
C7: Зион 193 жители | F7: тринити | G7: Якупов Марат Мансурович | H7: Yota | I7: 6063194562 | J7: Камеры | K7: 22 число | L7: 665 | O7: 0 | Q7: 0 | S7: 0 | U7: 0 | W7: 665 | X7: 45889 | Y7: 665 | Z7: 45856 | AA7: 665 | AB7: 45826 | AC7: 550 | AD7: 45797 | AE7: 550 | AF7: 45763
B8: 5 | C8: 195-193 dom | F8: тринити | G8: Якупов Марат Мансурович | H8: Yota | I8: 6063194562 | J8: Камеры | K8: 28 числа | L8: 650 | W8: отключили | X8: 45889 | Y8: 0 | AA8: 0 | AB8: 45826 | AC8: отключили | AE8: отключили | AG8: 600 | AH8: 45740 | AJ8: отключили | AK8: 650 | AL8: 45678
C9: 195-193 dom | F9: тринити | H9: билайн | I9: 8 962 212 5497 | K9: 18 числа и 5 | L9: 544 | O9: 544 | Q9: 544 | R9: 45979 | S9: 544 | T9: 45949 | U9: 544 | W9: 544 | X9: 272 | Y9: 544 | AA9: 544 | AC9: 544 | AD9: 45797 | AE9: 544 | AF9: 45763 | AG9: 550 | AH9: 45734 | AI9: 500 | AJ9: 45707
C10: 187 dom | F10: тринити | H10: билайн | I10: 962 206 60 97 | K10: 18 числа и 5 | L10: 500 | O10: 500 | Q10: 500 | R10: 45979 | S10: 500 | T10: 45949 | U10: 500 | W10: 500 | X10: 250 | Y10: 500 | AA10: 500 | AC10: 500 | AD10: 45797 | AE10: 500 | AF10: 45763
B11: 17 | C11: 155 dom эта симка на камеры жителей | F11: тринити | G11: Якупов Марат Мансурович | H11: Yota | I11: 6063194562 | J11: Камеры | K11: 22 числа | L11: 600 | P11: 46009 | W11: отключили | X11: 45889 | Y11: 0 | AA11: 0 | AB11: 45826 | AC11: отключили | AE11: отключили | AI11: 600 | AJ11: 45707 | AK11: 600 | AL11: 45678
C12: 145 дом, с него на 155 перекинем | E12: http://83.69.106.213 | F12: тринити | H12: Билайн | I12: 0894 472 296 | J12: Камеры | K12: 6 числа | L12: 1150 | O12: 1150 | P12: 46009 | Q12: 1150 | R12: 45999 | S12: 1150 | T12: 45949 | U12: 1150 | V12: 45919 | W12: 1150 | X12: 1150 | Y12: 1150 | Z12: 45861 | AA12: 1150 | AB12: 45826 | AC12: 1150 | AD12: 45797 | AE12: 1150 | AF12: 45763 | AG12: 1150 | AH12: 45730
B13: 19 | C13: 187 dom | F13: тринити | G13: Якупов Марат Мансурович | H13: Yota | I13: 6063194562 | J13: Камеры | K13: 01 числа | L13: 700 | W13: отключили | Y13: 0 | AA13: 0 | AB13: 45826 | AC13: отключили | AE13: отключили | AG13: 700 | AH13: 45735 | AI13: 700 | AJ13: 45707 | AK13: 700 | AL13: 45678
C14: 189 dom | F14: тринити | G14: Сафиуллин Раниф Рифхатович | H14: Yota | I14: 6064832807 | J14: Камеры | L14: 725 | O14: 725 | P14: 46009 | Q14: 725 | R14: 45979 | S14: 725 | T14: 45947 | U14: 725 | V14: 45919 | W14: 725 | X14: 45889 | Y14: 725 | Z14: 45861 | AA14: 725 | AB14: 45826 | AC14: 725 | AD14: 45797 | AE14: 600 | AF14: 45763 | AG14: 600 | AH14: 45735 | AI14: 600 | AJ14: 45707 | AK14: 600 | AL14: 45678
B15: 21 | C15: Центральная 169-171 | F15: тринити | G15: Сафиуллин Раниф Рифхатович | H15: Yota | I15: 6064832807 | J15: Камеры | K15: 23 числа | L15: 785 | O15: 0 | Q15: 0 | S15: 0 | U15: 0 | W15: 0 | X15: 0 | Y15: 785 | Z15: 45861 | AA15: 785 | AB15: 45826 | AC15: 785 | AD15: 45797 | AE15: 650 | AF15: 45763 | AG15: 1300 | AH15: 45735 | AI15: 650 | AJ15: 45706 | AK15: 650 | AL15: 45673
C16: Зион, Центральная 165 | F16: тринити | G16: Букин Александр | H16: таттелеком | I16: 105 891 794 | J16: Камеры | M16: 400 | O16: 400 | P16: 46009
C17: Напоминаем, для оплаты услуги интернет необходимо сделать перевод на карту Сбербанк 2202 2032 2647 9485 Тинькофф 5536 9139 3963 9122 В комментариях указав цифры абонентского номера «1176» | F17: ЗИОН | H17: Билайн | J17: Камеры | L17: 2500 | O17: 0 | P17: 0 | Q17: 0 | S17: 0 | U17: 0 | W17: 0 | X17: 0 | Y17: 0 | AA17: 0 | AB17: 0 | AC17: 0 | AE17: 0 | AG17: 2500 | AH17: 45735 | AI17: 2500 | AJ17: 45707 | AK17: 2500 | AL17: 45678
B18: 6 | C18: Зион-2 115 dom | F18: застройщик | G18: Якупов Марат Мансурович | H18: Yota | I18: 6063194562 | J18: Камеры | K18: 28 числа | L18: 665 | O18: 665 | P18: 46009 | Q18: 0 | S18: 665 | T18: 45947 | U18: 665 | V18: 45919 | W18: 665 | X18: 45889 | Y18: 665 | Z18: 45861 | AA18: 665 | AB18: 45826 | AC18: 550 | AD18: 45797 | AE18: 550 | AF18: 45763 | AG18: 550 | AH18: 45735 | AI18: 550 | AJ18: 45707 | AK18: 550 | AL18: 45678
B19: 7 | C19: Зион-2 135 dom | F19: застройщик | G19: Якупов Марат Мансурович | H19: Yota | I19: 6063194562 | J19: Камеры | K19: 20 числа | L19: 725 | O19: 725 | P19: 46009 | Q19: 725 | R19: 45979 | S19: 725 | T19: 45947 | U19: 725 | V19: 45919 | W19: 725 | X19: 45889 | Y19: 725 | Z19: 45861 | AA19: 1450 | AB19: 45826 | AC19: 725 | AD19: 45796 | AE19: 600 | AF19: 45763 | AG19: 1200 | AH19: 45735 | AI19: 600 | AJ19: 45706 | AK19: 600 | AL19: 45673
B20: 8 | C20: Зион-3 ЖК Комфорт камеры бытовки | F20: застройщик | G20: Якупов Марат Мансурович | H20: Yota | I20: 6063194562 | J20: Камеры | K20: 18 числа | L20: 665 | O20: 665 | P20: 46009 | Q20: 665 | R20: 45979 | S20: 665 | T20: 45947 | U20: 665 | V20: 45919 | W20: 665 | X20: 45889 | Y20: 665 | Z20: 45861 | AA20: 665 | AB20: 45826 | AC20: 665 | AD20: 45797 | AE20: 550 | AF20: 45763 | AG20: 550 | AH20: 45735 | AI20: 0 | AJ20: 550 | AK20: 550 | AL20: 45673
B21: 9 | C21: Зион-2 заезд | F21: застройщик | G21: Якупов Марат Мансурович | H21: Yota | I21: 6063194562 | J21: Камеры | K21: 19 числа | L21: 665 | O21: 665 | P21: 46009 | Q21: 665 | R21: 45979 | S21: 665 | T21: 45947 | U21: 665 | V21: 45919 | W21: 665 | X21: 45889 | Y21: 665 | Z21: 45861 | AA21: 665 | AB21: 45826 | AC21: 665 | AD21: 45797 | AE21: 550 | AF21: 45763 | AG21: 550 | AH21: 45735 | AI21: 0 | AJ21: 550 | AK21: 550 | AL21: 45673
B22: 10 | C22: Зион-2 101 dom | F22: застройщик | G22: Якупов Марат Мансурович | H22: Yota | I22: 6063194562 | J22: Камеры | K22: 6 числа | L22: 665 | O22: 665 | P22: 46009 | Q22: 665 | R22: 45979 | S22: 665 | T22: 45947 | U22: 665 | V22: 45919 | W22: 665 | X22: 45889 | Y22: 665 | Z22: 45861 | AA22: 665 | AB22: 45826 | AC22: 665 | AD22: 45797 | AE22: 550 | AF22: 45763 | AG22: 550 | AH22: 45735 | AI22: 550 | AJ22: 45707 | AK22: 550 | AL22: 45678
B23: 11 | C23: Зион-2 26 dom | F23: застройщик | G23: Якупов Марат Мансурович | H23: Yota | I23: 6063194562 | J23: Камеры | K23: 19 числа | L23: 665 | O23: 665 | P23: 46009 | Q23: 665 | R23: 45979 | S23: 665 | T23: 45947 | U23: 665 | V23: 45919 | W23: 665 | X23: 45889 | Y23: 665 | Z23: 45861 | AA23: 665 | AB23: 45826 | AC23: 665 | AD23: 45797 | AE23: 550 | AF23: 45763 | AG23: 550 | AH23: 45735 | AI23: 550 | AJ23: 45707 | AK23: 550 | AL23: 45673
B24: 12 | C24: Зион-2 139 dom | F24: застройщик | G24: Якупов Марат Мансурович | H24: Yota | I24: 6063194562 | J24: Камеры | K24: 6 числа | L24: 665 | O24: 665 | P24: 46009 | Q24: 665 | R24: 45979 | S24: 665 | T24: 45947 | U24: 665 | V24: 45919 | W24: 665 | X24: 45889 | Y24: 665 | Z24: 45861 | AA24: 665 | AB24: 45826 | AC24: 665 | AD24: 45797 | AE24: 550 | AF24: 45763 | AG24: 550 | AH24: 45735 | AI24: 550 | AJ24: 45707 | AK24: 550 | AL24: 45678
