Workbook

Sheet ЭРТХА доп работы
A1: Наименование доп.работы | B1: Цена | C1: Кол-во | D1: Итого | E1: Кол-во чел-к | F1: К оплате
A2: Подключение или замена Аудио трубки | B2: 150 | C2: 9 | D2: =B2*C2 -> 1350 | E2: 2 | F2: =D2/E2 -> 675
A3: Подключение или замена Аудиотрубки с протяжкой абон линий | B3: 350 | D3: =B3*C3 -> 0 | E3: 2 | F3: =D3/E3 -> 0
A4: Подключение или замена Видеомонитора | B4: 400 | D4: =B4*C4 -> 0 | E4: 2 | F4: =D4/E4 -> 0
A5: Подключение или замена Видеоманитора с кабелем и с установкой видеоделителем на этаже | B5: 700 | D5: =B5*C5 -> 0 | E5: 2 | F5: =D5/E5 -> 0
A6: Продажа и прописание ключа на домофон | B6: 100 | C6: 1 | D6: =B6*C6 -> 100 | E6: 2 | F6: =D6/E6 -> 50

Sheet ПЕРЕРАСЧЕТЫ ПО РЕБЯТАМ
A1: ФИО | B1: Комментарии
A2: Садриев | B2: С матра уменьшить ко-во домоф по ВН, у нег получается будет 9 домов. И вычесть - 800 за то что в феврале оплатили. Кулахметова 25 к1 ушли с января 2025 | D2: учтено
A3: Балашов | B3: добавить 5500 за гофру и ЮТР | D3: учтено
A4: Балашов | B4: с апреля добавить одесскую 44 к 1 1 дом 800 р | D4: учтено
A5: Балашов | B5: в марте +2000 за прояжку линии в офис | D5: учтено
A7: Диляра | B7: Мониторинг считать по 72 руб. | D7: учтено
A9: Артем | B9: Сделать добавку 1000 за выезд на срочную заявку вечером в выходной день | D9: учтено
A10: Балашов | B10: Монтаж на Луначарского 36 с 1 по 4 под. - 12 000 | D10: учтено
A11: Сагов | B11: Покраска дверей с двух сторон по К.Ц.21 - 8 000 +32000 | D11: учтено
A12: Балашов | B12: Монтаж на Гастелло 71 с 1 по 4 под. - 10 000 | D12: учтено
A13: Диляра | B13: 12.06*1300, 13, 14,15 июня считать по 1300 | D13: учтено

Sheet Лист45
A1: Тер-я Дениса | B1: Кол-во под. | C1: Цена за под.
A2: Тер-я Дениса | B2: 238 | C2: 147 | D2: =B2*C2 -> 34986
A3: Тер-я Артема | B3: 276 | D3: 30000
A4: Общая сумма | B4: =SUM(B2:B3) -> 514 | D4: =SUM(D2:D3) -> 64986
A6: Тер-я Дениса | B6: Кол-во под. | C6: Цена за под.
A7: Тер-я Дениса | B7: 238 | C7: 147 | D7: =B7*C7 -> 34986
A8: Тер-я Артема | B8: 276 | C8: 147 | D8: =B8*C8 -> 40572
A9: Общая сумма | B9: =SUM(B7:B8) -> 514 | D9: =SUM(D7:D8) -> 75558
A11: Тер-я Дениса | B11: Кол-во под. | C11: Цена за под.
A12: Тер-я Дениса | B12: 238 | C12: 100 | D12: =B12*C12 -> 23800
A13: Тер-я Артема | B13: 276 | C13: 100 | D13: =B13*C13 -> 27600
A14: Общая сумма | B14: =SUM(B12:B13) -> 514 | D14: =SUM(D12:D13) -> 51400
A16: Тер-я Дениса | B16: Кол-во под. | C16: Цена за под.
A17: Тер-я Дениса | B17: 238 | C17: 130 | D17: =B17*C17 -> 30940
A18: Тер-я Артема | B18: 276 | C18: 130 | D18: =B18*C18 -> 35880
A19: Общая сумма | B19: =SUM(B17:B18) -> 514 | D19: =SUM(D17:D18) -> 66820
A21: Тер-я Дениса | B21: Кол-во под. | C21: Цена за под.
A22: Тер-я Дениса | B22: 238 | C22: 130 | D22: =B22*C22 -> 30940
A23: Тер-я Артема | B23: 276 | C23: 130 | D23: =B23*C23 -> 35880
A24: Общая сумма | B24: =SUM(B22:B23) -> 514 | D24: =SUM(D22:D23) -> 66820

Sheet декабрь
A2: Сервис партнер | B2: ФИО инженера | C2: подъездов/камер/домов | D2: ставка | E2: Оклад | F2: ГСМ | G2: Комиссия/Налоги | H2: Доп.работы | I2: покупка оборудования | J2: Оплата за монтажи кап вложения | K2: Оплата за монтажи сервис | L2: Оплата за монтажи модернизация | M2: ЭРТХА | N2: Удержание | O2: К выплате | P2: выплатили | Q2: доплата
B3: Садриев Ильдус | C3: 84 | D3: 100 | E3: =(C3*D3)+9600 -> 18000 | G3: 1778.76 | O3: =E3+F3+G3+H3+L3+M3-N3+I3+J3+K3 -> 19778.76 | R3: оплачено
B4: Нуретдинов Рафаэль (ВН) | E4: 10000 | G4: 638.28 | O4: =E4+F4+G4+H4+L4+M4-N4+I4+J4+K4 -> 10638.28 | R4: оплачено
A5: Самозанятый | B5: Богдан | C5: 333 | D5: 120 | E5: =39960+2500 -> 42460 | G5: =4793.52+2985.24 -> 7778.76 | H5: 2500 | O5: =E5+F5+G5+H5+L5+M5-N5+I5+J5+K5 -> 52738.76 | P5: 52739 | Q5: 0 | R5: оплачено
A6: Самозанятый | B6: Диляра (КЦ) | E6: =16500+10400+2000+2418+2600 -> 33918
A7: Самозанятый | B7: Калачев Артем | C7: 645 | D7: 100.11 | E7: =645*100 -> 64500 | F7: 5500 | G7: =8222.22+8894.4 -> 17116.62 | H7: 10000 | L7: =12000+12000 -> 24000 | O7: =E7+F7+E8+G7+H7+M7+N7+E6+H6+L7+K7 -> 157134.62 | P7: 123135 | Q7: 34000 | R7: оплачено
A8: Самозанятый | C8: 42 | D8: 50 | E8: =C8*D8 -> 2100
A9: Самозанятый | B9: Полуянов И. | C9: =351+16 -> 367 | D9: 100 | E9: =C9*D9 -> 36700 | F9: 10000 | G9: =3317.1+3266.46 -> 6583.56 | O9: =E9+E10+F9+G9+L9+H9+M9-N9 -> 57707.56 | P9: 57708 | Q9: 0 | R9: оплачено
A10: Самозанятый | C10: 28 | D10: 158 | E10: =C10*D10 -> 4424
O11: =SUM(O5:O10) -> 267580.94
A12: Самозанятый | B12: Касимов А. | C12: 499 | D12: 50 | E12: =24950+2500+4000 -> 31450 | G12: =2007.48+5427.42 -> 7434.9 | L12: =27000+27000+3000 -> 57000 | O12: =E12+F12+G12+H12+L12+M12-N12+I12+J12+K12 -> 95884.9 | P12: 38885 | Q12: 57000 | R12: пп
A13: Самозанятый | B13: Воронцов Денис | C13: =215+8+15 -> 238 | D13: 147 | E13: =C13*D13 -> 34986 | G13: =2280.84+2236.02 -> 4516.86 | O13: =E13+F13+G13+H13+L13+M13-N13+I13 -> 39502.86 | P13: 39503 | Q13: 0 | R13: оплачено
A14: Самозанятый | B14: Балашов Виталий | C14: 26 | D14: 800 | E14: =D14*C14 -> 20800 | G14: 8166.4 | H14: 800 | J14: =9000+77000+20000 -> 106000 | O14: =E14+K14+G14+J14+H14 -> 135766.4 | Q14: 135766
B15: Олег/Артем | E15: 30000 | H15: =1200+2000+3000 -> 6200 | O15: =E15+F15+G15+H15+M15-N15+I15+J15 -> 36200 | P15: 36200 | Q15: 0 | R15: оплачено
B16: Илья | M16: =62621.19 -> 62621.19 | O16: =M16+G16-N16 -> 62621.19 | P16: 62621 | Q16: 0 | R16: оплачено
B17: Костя | M17: =62621.19 -> 62621.19 | O17: =M17+G17-N17 -> 62621.19 | P17: 62621 | Q17: 0 | R17: оплачено
B18: Гусейнов Артем | M18: 42800 | O18: =M18+G18 -> 42800 | P18: 42800 | Q18: 0 | R18: оплачено
A19: ИТОГО | C19: =SUM(C9:C13) -> 1132 | E19: =SUM(E9:E17) -> 158360 | F19: =SUM(F9:F14) -> 10000 | G19: =SUM(G9:G17) -> 26701.72 | H19: =SUM(H9:H17) -> 7000 | I19: =SUM(I9:I18) -> 0 | J19: =SUM(J9:J18) -> 106000 | K19: =SUM(K9:K18) -> 0 | L19: =SUM(L9:L18) -> 57000 | M19: =SUM(M9:M18) -> 168042.38 | N19: =SUM(N9:N14) -> 0 | O19: =SUM(O12:O18) -> 475396.54
M20: ОБЩАЯ СУММА | O20: =SUM(O11+O19) -> 742977.48
E21: =E6+'ноябрь'!E8+'октябрь'!E8+'сентябрь'!E8+'август'!E8+'июль'!E8+'май'!E7+'июнь'!E7+'апрель'!E7+'март'!E7+'февраль'!E7+'январь'!E7 -> 389926 | F21: 12 | G21: =E21/F21 -> 32493.833
E31: =E22+E24+E26 -> 0 | F31: 6 | G31: =E31/F31 -> 0
D34: Диляра | E34: =#REF!+'май'!E7+'апрель'!E7+'май'!H7+'март'!E7+'февраль'!E7+'январь'!E7 -> #REF! | F34: 6 | G34: =E34/F34 -> #REF!
E36: ВН | F36: ДО | G36: Налог | H36: итого
D37: Ильдус | E37: =8000+8000+7200+7200+7200+72000 -> 109600 | F37: =840+840+840+840+840+840+6708 -> 11748 | G37: =G9+'май'!G3+'апрель'!G3+'март'!G3+'февраль'!G3+'январь'!G3/2 -> 12404.54
E38: 6 | F38: 6 | G38: 6
E39: =E37/E38+G39 -> 20334.09 | F39: =F37/F38 -> 1958 | G39: =G37/G38 -> 2067.4233
D41: Рафаэль | E41: =E10+'май'!E4+'апрель'!E4+'март'!E4+'февраль'!E4+'январь'!E4 -> 54424 | G41: =G10+'май'!G4+'апрель'!G4+'март'!G4+'февраль'!G4+'январь'!G4 -> 3191.58
E42: 6 | G42: 6
E43: =E41/E42+G43 -> 9602.5967 | G43: =G41/G42 -> 531.93
I44: Гараж+админ
D45: Касимов | E45: =22950+22950+23250+23250+24850+24850 -> 142100 | F45: =43800+43800+39960+39960+39960+39960 -> 247440 | G45: =(G12+'май'!G5+'апрель'!G5+'март'!G5+'февраль'!G5+'январь'!G5)/2 -> 18480.8 | I45: =54000/2 -> 27000
E46: 6 | F46: 6 | G46: 6 | I46: 6
E47: =E45/E46+G47+I47 -> 31263.467 | F47: =F45/F46+G47+I47 -> 48820.133 | G47: =G45/G46 -> 3080.1333 | I47: =I45/I46 -> 4500
D49: Воронцов | F49: ='май'!O6+'апрель'!O6+'март'!O6+'февраль'!N6+'январь'!N6+O13 -> 229739.14
F50: 6
F51: =F49/F50 -> 38289.857
D53: Калачев | E53: =33000+3000 -> 36000 | F53: =#REF!+#REF!+'май'!E8+'май'!E9+'май'!H8+'апрель'!E8+'апрель'!E9+'апрель'!H8+'март'!E8+'март'!E9+'февраль'!E8+'февраль'!E9+'январь'!E8+'январь'!E9 -> #REF! | G53: =#REF!+'май'!G8+'апрель'!G8+'март'!G8+'февраль'!G8+'январь'!G8 -> #REF!
E54: 6 | F54: 6 | G54: 6
E55: =E53/E54 -> 6000 | F55: =F53/F54+G55 -> #REF! | G55: =G53/G54 -> #REF!
D57: Полуянов | F57: =#REF!+'май'!O10+'апрель'!O10+'март'!O10+'февраль'!N10+'январь'!N10 -> #REF!
...

Sheet ноябрь
A2: Сервис партнер | B2: ФИО инженера | C2: подъездов/камер/домов | D2: ставка | E2: Оклад | F2: ГСМ | G2: Комиссия/Налоги | H2: Доп.работы | I2: покупка оборудования | J2: Оплата за монтажи кап вложения | K2: Оплата за монтажи сервис | L2: Оплата за монтажи модернизация | M2: ЭРТХА | N2: Удержание | O2: К выплате | P2: выплатили | Q2: доплата
A3: Самозанятый | B3: Садриев Ильдус | C3: 84 | D3: 100 | E3: =(C3*D3)+9600 -> 18000 | G3: 1145.94 | H3: =500+10000 -> 10500 | O3: =E3+F3+G3+H3+L3+M3-N3 -> 29645.94
A4: Самозанятый | B4: Нуретдинов Рафаэль (ВН) | E4: 10000 | G4: 638.28 | O4: =E4+F4+G4+H4+L4+M4-N4 -> 10638.28
A5: Самозанятый | B5: Касимов А. | C5: 499 | D5: 50 | E5: =24950+2500+4000 -> 31450 | G5: 2008.2 | O5: =E5+F5+G5+H5+L5+M5-N5+I5+J5+K5 -> 33458.2
A6: Самозанятый | B6: Богдан | C6: 333 | D6: 120 | E6: =39960+2500 -> 42460 | G6: 2931.54 | L6: =30000+4500 -> 34500 | O6: =E6+F6+G6+H6+L6+M6-N6+I6+J6+K6 -> 79891.54
A7: Самозанятый | B7: Воронцов Денис | C7: =184+8+8+8+2+5 -> 215 | D7: 147 | E7: =C7*D7 -> 31605 | G7: 4509.48 | H7: =900+1000 -> 1900 | O7: =E7+F7+G7+H7+L7+M7-N7+I7 -> 38014.48
A8: Самозанятый | B8: Диляра (КЦ) | E8: =34190 -> 34190
A9: Самозанятый | B9: Калачев Артем | C9: 645 | D9: 100.11 | E9: =645*100 -> 64500 | F9: 5500 | G9: 6747.36 | L9: =12000+12000 -> 24000 | O9: =E9+F9+E10+G9+H9+M9+N9+E8+H8+L9+K9 -> 137037.36
A10: Самозанятый | C10: 42 | D10: 50 | E10: =C10*D10 -> 2100
A11: Самозанятый | B11: Полуянов И. | C11: =351+16 -> 367 | D11: 100 | E11: =C11*D11 -> 36700 | F11: 10000 | G11: 3161.1 | H11: 1000 | O11: =E11+E12+F11+G11+L11+H11+M11-N11 -> 55285.1
A12: Самозанятый | C12: 28 | D12: 158 | E12: =C12*D12 -> 4424
A13: Самозанятый | B13: Балашов Виталий | C13: 23 | D13: 800 | E13: =C13*D13 -> 18400 | H13: 1000 | J13: =3500+85500+16500 -> 105500 | O13: =E13+K13+G13+J13+H13 -> 124900
B14: Олег | E14: 30000 | O14: =E14+F14+G14+H14+M14-N14+I14+J14 -> 30000
B15: Илья | M15: =62822.6 -> 62822.6 | O15: =M15+G15-N15 -> 62822.6
B16: Костя | M16: =62822.6 -> 62822.6 | O16: =M16+G16-N16 -> 62822.6
B17: Гусейнов Артем | M17: 42800 | O17: =M17+G17 -> 42800
A18: ИТОГО | C18: =SUM(C3:C9) -> 1776 | E18: =SUM(E3:E16) -> 323829 | F18: =SUM(F3:F13) -> 15500 | G18: =SUM(G3:G16) -> 21141.9 | H18: =SUM(H3:H16) -> 14400 | I18: =SUM(I3:I17) -> 0 | J18: =SUM(J3:J17) -> 105500 | K18: =SUM(K3:K17) -> 0 | L18: =SUM(L3:L17) -> 58500 | M18: =SUM(M3:M17) -> 168445.2 | N18: =SUM(N3:N13) -> 0 | O18: =SUM(O3:O17) -> 707316.1
P20: =SUM(P3:P17) -> 0 | Q20: =SUM(Q3:Q17) -> 0
D21: ФОТ | E21: =O18+'май'!O17+'апрель'!O17+'март'!O17+'февраль'!N17+'январь'!N17 -> 3824782.8 | O21: =O16+O14+O13 -> 217722.6
O22: =O4+O5+O7+O9+O3+O17+O15 -> 354416.86 | P22: =Q13+O14 -> 30000
D23: МОНТАЖИ | E23: =J18+K18+L18+'май'!J17+'май'!K17+'май'!L17+'апрель'!L17+'март'!J17+'март'!L17+'февраль'!I17+'февраль'!J17+'февраль'!K17+'январь'!K17 -> 555700 | F23: 6 | G23: =E23/F23 -> 92616.667 | I23: =E8+'август'!E8+'июль'!E8+'июнь'!E7+'май'!E7+'апрель'!E7+'март'!E7+'февраль'!E7+'январь'!E7 -> 292700
D25: оборудование | E25: =I18+'март'!I17 -> 21500 | O25: =O18+'октябрь'!O18+'сентябрь'!O19+'август'!O19+'июль'!O18+'июнь'!O17+'май'!O17+'апрель'!O17+'март'!O17+'февраль'!N17+'январь'!N17 -> 7627780.8
D27: ФОТ за минусом | E27: =E21-E23-E25 -> 3247582.8 | F27: 6 | G27: =E27/F27 -> 541263.8 | O27: =O7+O11+O13+O14+'октябрь'!O7+'октябрь'!O11+'октябрь'!O13+'октябрь'!O14+'сентябрь'!O7+'сентябрь'!O11+'сентябрь'!O13+'сентябрь'!O14+'август'!O7+'август'!O11+'август'!O13+'август'!O14+'июль'!O7+'июль'!O11+'июль'!O13+'июль'!O14+'июнь'!O6+'июнь'!O10+'июнь'!O12+'июнь'!O13+'май'!O6+'май'!O10+'май'!O12+'май'!O13+'апрель'!O6+'апрель'!O10+'апрель'!O12+'апрель'!O13+'март'!O6+'март'!O10+'март'!O12+'март'!O13+'февраль'!N6+'февраль'!N10+'февраль'!N12+'февраль'!N13+'январь'!N6+'январь'!N10+'январь'!N12+'январь'!N13 -> 2585039.1
E30: =E21+E23+E25 -> 4401982.8 | F30: 6 | G30: =E30/F30 -> 733663.8
D33: Диляра | E33: =E8+'май'!E7+'апрель'!E7+'май'!H7+'март'!E7+'февраль'!E7+'январь'!E7 -> 200414 | F33: 6 | G33: =E33/F33 -> 33402.333
E35: ВН | F35: ДО | G35: Налог | H35: итого
D36: Ильдус | E36: =8000+8000+7200+7200+7200+72000 -> 109600 | F36: =840+840+840+840+840+840+6708 -> 11748 | G36: =G3+'май'!G3+'апрель'!G3+'март'!G3+'февраль'!G3+'январь'!G3/2 -> 6966.92
E37: 6 | F37: 6 | G37: 6
E38: =E36/E37+G38 -> 19427.82 | F38: =F36/F37 -> 1958 | G38: =G36/G37 -> 1161.1533
D40: Рафаэль | E40: =E4+'май'!E4+'апрель'!E4+'март'!E4+'февраль'!E4+'январь'!E4 -> 60000 | G40: =G4+'май'!G4+'апрель'!G4+'март'!G4+'февраль'!G4+'январь'!G4 -> 3829.86
E41: 6 | G41: 6
E42: =E40/E41+G42 -> 10638.31 | G42: =G40/G41 -> 638.31
I43: Гараж+админ
D44: Касимов | E44: =22950+22950+23250+23250+24850+24850 -> 142100 | F44: =43800+43800+39960+39960+39960+39960 -> 247440 | G44: =(G5+'май'!G5+'апрель'!G5+'март'!G5+'февраль'!G5+'январь'!G5)/2 -> 15767.45 | I44: =54000/2 -> 27000
E45: 6 | F45: 6 | G45: 6 | I45: 6
E46: =E44/E45+G46+I46 -> 30811.242 | F46: =F44/F45+G46+I46 -> 48367.908 | G46: =G44/G45 -> 2627.9083 | I46: =I44/I45 -> 4500
D48: Воронцов | F48: ='май'!O6+'апрель'!O6+'март'!O6+'февраль'!N6+'январь'!N6+O7 -> 228250.76
F49: 6
F50: =F48/F49 -> 38041.793
D52: Калачев | E52: =33000+3000 -> 36000 | F52: =E9+E10+'май'!E8+'май'!E9+'май'!H8+'апрель'!E8+'апрель'!E9+'апрель'!H8+'март'!E8+'март'!E9+'февраль'!E8+'февраль'!E9+'январь'!E8+'январь'!E9 -> 407440 | G52: =G9+'май'!G8+'апрель'!G8+'март'!G8+'февраль'!G8+'январь'!G8 -> 44964.56
...

Sheet октябрь
A2: Сервис партнер | B2: ФИО инженера | C2: подъездов/камер/домов | D2: ставка | E2: Оклад | F2: ГСМ | G2: Комиссия/Налоги | H2: Доп.работы | I2: покупка оборудования | J2: Оплата за монтажи кап вложения | K2: Оплата за монтажи сервис | L2: Оплата за монтажи модернизация | M2: ЭРТХА | N2: Удержание | O2: К выплате | P2: выплатили | Q2: доплата
A3: Самозанятый | B3: Садриев Ильдус | C3: 84 | D3: 100 | E3: =(C3*D3)+9600 -> 18000 | G3: 1098.54 | O3: =E3+F3+G3+H3+L3+M3-N3 -> 19098.54 | P3: 19099
A4: Самозанятый | B4: Нуретдинов Рафаэль (ВН) | E4: 10000 | G4: 638.28 | O4: =E4+F4+G4+H4+L4+M4-N4 -> 10638.28 | P4: 10638
A5: Самозанятый | B5: Касимов А. | C5: 499 | D5: 50 | E5: =24950+2500+4000 -> 31450 | G5: 2020.32 | O5: =E5+F5+G5+H5+L5+M5-N5+I5+J5+K5 -> 33470.32 | P5: 33470
A6: Самозанятый | B6: Богдан | C6: 333 | D6: 120 | E6: =39960+2500 -> 42460 | G6: 3399 | K6: 3000 | O6: =E6+F6+G6+H6+L6+M6-N6+I6+J6+K6 -> 48859 | P6: 48859
A7: Самозанятый | B7: Воронцов Денис | C7: 215 | D7: 147 | E7: =C7*D7 -> 31605 | G7: 3053.4 | I7: 500 | L7: =5000+5000 -> 10000 | O7: =E7+F7+G7+H7+L7+M7-N7+I7 -> 45158.4 | P7: 45158
A8: Самозанятый | B8: Диляра (КЦ) | E8: =17250+10400+2000+2418 -> 32068
A9: Самозанятый | B9: Калачев Артем | C9: 645 | D9: 100.11 | E9: =645*100 -> 64500 | F9: 5500 | G9: 8288.4 | O9: =E9+F9+E10+G9+H9+M9+N9+E8+H8+L9+K9 -> 112456.4 | P9: 112456
A10: Самозанятый | C10: 42 | D10: 50 | E10: =C10*D10 -> 2100
A11: Самозанятый | B11: Полуянов И. | C11: 351 | D11: 100 | E11: =C11*D11 -> 35100 | F11: 10000 | G11: 3161.1 | O11: =E11+E12+F11+G11+L11+H11+M11-N11 -> 52685.1 | P11: 52685
A12: Самозанятый | C12: 28 | D12: 158 | E12: =C12*D12 -> 4424
A13: Самозанятый | B13: Балашов Виталий | C13: 22 | D13: 800 | E13: =C13*D13 -> 17600 | G13: 12582.4 | J13: =8000+24000+139000 -> 171000 | K13: =4600+2000+1000+400 -> 8000 | O13: =E13+K13+G13+J13+H13 -> 209182.4 | Q13: 208565
B14: Олег | E14: 30000 | O14: =E14+F14+G14+H14+M14-N14+I14+J14 -> 30000 | P14: 30000
B15: Илья | M15: =59865.19 -> 59865.19 | O15: =M15+G15-N15 -> 59865.19 | Q15: 59865
B16: Костя | M16: =59865.19 -> 59865.19 | O16: =M16+G16-N16 -> 59865.19 | Q16: 59865
B17: Гусейнов Артем | M17: 42800 | O17: =M17+G17 -> 42800 | P17: 42800
A18: ИТОГО | C18: =SUM(C3:C9) -> 1776 | E18: =SUM(E3:E16) -> 319307 | F18: =SUM(F3:F13) -> 15500 | G18: =SUM(G3:G16) -> 34241.44 | H18: =SUM(H3:H16) -> 0 | I18: =SUM(I3:I17) -> 500 | J18: =SUM(J3:J17) -> 171000 | K18: =SUM(K3:K17) -> 11000 | L18: =SUM(L3:L17) -> 10000 | M18: =SUM(M3:M17) -> 162530.38 | N18: =SUM(N3:N13) -> 0 | O18: =SUM(O3:O17) -> 724078.82
P20: =SUM(P3:P17) -> 395165 | Q20: =SUM(Q3:Q17) -> 328295
D21: ФОТ | E21: =O18+'май'!O17+'апрель'!O17+'март'!O17+'февраль'!N17+'январь'!N17 -> 3841545.5 | O21: =O16+O14+O13 -> 299047.59
O22: =O4+O5+O7+O9+O3+O17+O15 -> 323487.13 | P22: =Q13+O14 -> 238565
D23: МОНТАЖИ | E23: =J18+K18+L18+'май'!J17+'май'!K17+'май'!L17+'апрель'!L17+'март'!J17+'март'!L17+'февраль'!I17+'февраль'!J17+'февраль'!K17+'январь'!K17 -> 583700 | F23: 6 | G23: =E23/F23 -> 97283.333 | I23: =E8+'август'!E8+'июль'!E8+'июнь'!E7+'май'!E7+'апрель'!E7+'март'!E7+'февраль'!E7+'январь'!E7 -> 290578
D25: оборудование | E25: =I18+'март'!I17 -> 22000
D27: ФОТ за минусом | E27: =E21-E23-E25 -> 3235845.5 | F27: 6 | G27: =E27/F27 -> 539307.59
E30: =E21+E23+E25 -> 4447245.5 | F30: 6 | G30: =E30/F30 -> 741207.59
D33: Диляра | E33: =E8+'май'!E7+'апрель'!E7+'май'!H7+'март'!E7+'февраль'!E7+'январь'!E7 -> 198292 | F33: 6 | G33: =E33/F33 -> 33048.667
E35: ВН | F35: ДО | G35: Налог | H35: итого
D36: Ильдус | E36: =8000+8000+7200+7200+7200+72000 -> 109600 | F36: =840+840+840+840+840+840+6708 -> 11748 | G36: =G3+'май'!G3+'апрель'!G3+'март'!G3+'февраль'!G3+'январь'!G3/2 -> 6919.52
E37: 6 | F37: 6 | G37: 6
E38: =E36/E37+G38 -> 19419.92 | F38: =F36/F37 -> 1958 | G38: =G36/G37 -> 1153.2533
D40: Рафаэль | E40: =E4+'май'!E4+'апрель'!E4+'март'!E4+'февраль'!E4+'январь'!E4 -> 60000 | G40: =G4+'май'!G4+'апрель'!G4+'март'!G4+'февраль'!G4+'январь'!G4 -> 3829.86
E41: 6 | G41: 6
E42: =E40/E41+G42 -> 10638.31 | G42: =G40/G41 -> 638.31
I43: Гараж+админ
D44: Касимов | E44: =22950+22950+23250+23250+24850+24850 -> 142100 | F44: =43800+43800+39960+39960+39960+39960 -> 247440 | G44: =(G5+'май'!G5+'апрель'!G5+'март'!G5+'февраль'!G5+'январь'!G5)/2 -> 15773.51 | I44: =54000/2 -> 27000
E45: 6 | F45: 6 | G45: 6 | I45: 6
E46: =E44/E45+G46+I46 -> 30812.252 | F46: =F44/F45+G46+I46 -> 48368.918 | G46: =G44/G45 -> 2628.9183 | I46: =I44/I45 -> 4500
D48: Воронцов | F48: ='май'!O6+'апрель'!O6+'март'!O6+'февраль'!N6+'январь'!N6+O7 -> 235394.68
F49: 6
F50: =F48/F49 -> 39232.447
D52: Калачев | E52: =33000+3000 -> 36000 | F52: =E9+E10+'май'!E8+'май'!E9+'май'!H8+'апрель'!E8+'апрель'!E9+'апрель'!H8+'март'!E8+'март'!E9+'февраль'!E8+'февраль'!E9+'январь'!E8+'январь'!E9 -> 407440 | G52: =G9+'май'!G8+'апрель'!G8+'март'!G8+'февраль'!G8+'январь'!G8 -> 46505.6
...

Sheet сентябрь
A2: Сервис партнер | B2: ФИО инженера | C2: подъездов/камер/домов | D2: ставка | E2: Оклад | F2: ГСМ | G2: Комиссия/Налоги | H2: Доп.работы | I2: покупка оборудования | J2: Оплата за монтажи кап вложения | K2: Оплата за монтажи сервис | L2: Оплата за монтажи модернизация | M2: ЭРТХА | N2: Удержание | O2: К выплате | P2: выплатили | Q2: доплата
A3: Самозанятый | B3: Садриев Ильдус | C3: 84 | D3: 100 | E3: =(C3*D3)+8800 -> 17200 | G3: 1108.92 | O3: =E3+F3+G3+H3+L3+M3-N3 -> 18308.92
A4: Самозанятый | B4: Нуретдинов Рафаэль (ВН) | E4: 10000 | G4: 638.28 | O4: =E4+F4+G4+H4+L4+M4-N4 -> 10638.28
A5: Самозанятый | B5: Касимов А. | C5: 499 | D5: 50 | E5: =24950+2500+4000 -> 31450 | G5: 2221.92 | O5: =E5+F5+G5+H5+L5+M5-N5+I5+J5+K5 -> 33671.92
A6: Самозанятый | B6: Богдан | C6: 333 | D6: 120 | E6: =39960+2500 -> 42460 | G6: 3989.88 | K6: 10200 | O6: =E6+F6+G6+H6+L6+M6-N6+I6+J6+K6 -> 56649.88
A7: Самозанятый | B7: Воронцов Денис | C7: 215 | D7: 147 | E7: =C7*D7 -> 31605 | G7: 3285.42 | H7: =5000+9000 -> 14000 | I7: =4*500 -> 2000 | O7: =E7+F7+G7+H7+L7+M7-N7+I7 -> 50890.42
A8: Самозанятый | B8: Диляра (КЦ) | E8: =16500+10400+2000+2340 -> 31240
A9: Самозанятый | B9: Калачев Артем | C9: 645 | D9: 100.11 | E9: =645*100 -> 64500 | F9: 5500 | G9: 9799.62 | H9: 1000 | L9: 24000 | O9: =E9+F9+E10+G9+H9+M9+N9+E8+H8+L9+K9 -> 138139.62
A10: Самозанятый | C10: 42 | D10: 50 | E10: =C10*D10 -> 2100
A11: Самозанятый | B11: Полуянов И. | C11: 351 | D11: 100 | E11: =C11*D11 -> 35100 | F11: 10000 | G11: 3160.98 | O11: =E11+E12+F11+G11+L11+H11+M11-N11 -> 52684.98
A12: Самозанятый | C12: 28 | D12: 158 | E12: =C12*D12 -> 4424
A13: Самозанятый | B13: Балашов Виталий | C13: 22 | D13: 800 | E13: =C13*D13 -> 17600 | G13: 9945.6 | J13: =38000+85000+3500 -> 126500 | K13: =14800-3500 -> 11300 | O13: =E13+K13+G13+J13+H13 -> 165345.6 | P13: 69000 | Q13: =O13-P13 -> 96345.6
B14: Олег | E14: 30000 | H14: =500+130+500+500+130 -> 1760 | O14: =E14+F14+G14+H14+M14-N14+I14+J14 -> 31760
I15: 22000 | J15: 34000
B16: Илья | M16: =62621.91 -> 62621.91 | O16: =M16+G16 -> 62621.91
B17: Костя | M17: =62621.91 -> 62621.91 | O17: =M17+G17 -> 62621.91
B18: Гусейнов Артем | M18: 42800 | O18: =M18+G18 -> 42800
A19: ИТОГО | C19: =SUM(C3:C9) -> 1776 | E19: =SUM(E3:E17) -> 317679 | F19: =SUM(F3:F13) -> 15500 | G19: =SUM(G3:G17) -> 34150.62 | H19: =SUM(H3:H17) -> 16760 | I19: =SUM(I3:I18) -> 24000 | J19: =SUM(J3:J18) -> 160500 | K19: =SUM(K3:K18) -> 21500 | L19: =SUM(L3:L18) -> 24000 | M19: =SUM(M3:M18) -> 168043.82 | N19: =SUM(N3:N13) -> 0 | O19: =SUM(O3:O18) -> 726133.44
D22: ФОТ | E22: =O19+'май'!O17+'апрель'!O17+'март'!O17+'февраль'!N17+'январь'!N17 -> 3843600.2 | O22: =O17+O14+O13 -> 259727.51
O23: =O4+O5+O7+O9+O3+O18+O16 -> 357071.07 | P23: =Q13+O14 -> 128105.6
D24: МОНТАЖИ | E24: =J19+K19+L19+'май'!J17+'май'!K17+'май'!L17+'апрель'!L17+'март'!J17+'март'!L17+'февраль'!I17+'февраль'!J17+'февраль'!K17+'январь'!K17 -> 597700 | F24: 6 | G24: =E24/F24 -> 99616.667 | I24: =E8+'август'!E8+'июль'!E8+'июнь'!E7+'май'!E7+'апрель'!E7+'март'!E7+'февраль'!E7+'январь'!E7 -> 289750
D26: оборудование | E26: =I19+'март'!I17 -> 45500
D28: ФОТ за минусом | E28: =E22-E24-E26 -> 3200400.2 | F28: 6 | G28: =E28/F28 -> 533400.03
E31: =E22+E24+E26 -> 4486800.2 | F31: 6 | G31: =E31/F31 -> 747800.03
D34: Диляра | E34: =E8+'май'!E7+'апрель'!E7+'май'!H7+'март'!E7+'февраль'!E7+'январь'!E7 -> 197464 | F34: 6 | G34: =E34/F34 -> 32910.667
E36: ВН | F36: ДО | G36: Налог | H36: итого
D37: Ильдус | E37: =8000+8000+7200+7200+7200+72000 -> 109600 | F37: =840+840+840+840+840+840+6708 -> 11748 | G37: =G3+'май'!G3+'апрель'!G3+'март'!G3+'февраль'!G3+'январь'!G3/2 -> 6929.9
E38: 6 | F38: 6 | G38: 6
E39: =E37/E38+G39 -> 19421.65 | F39: =F37/F38 -> 1958 | G39: =G37/G38 -> 1154.9833
D41: Рафаэль | E41: =E4+'май'!E4+'апрель'!E4+'март'!E4+'февраль'!E4+'январь'!E4 -> 60000 | G41: =G4+'май'!G4+'апрель'!G4+'март'!G4+'февраль'!G4+'январь'!G4 -> 3829.86
E42: 6 | G42: 6
E43: =E41/E42+G43 -> 10638.31 | G43: =G41/G42 -> 638.31
I44: Гараж+админ
D45: Касимов | E45: =22950+22950+23250+23250+24850+24850 -> 142100 | F45: =43800+43800+39960+39960+39960+39960 -> 247440 | G45: =(G5+'май'!G5+'апрель'!G5+'март'!G5+'февраль'!G5+'январь'!G5)/2 -> 15874.31 | I45: =54000/2 -> 27000
E46: 6 | F46: 6 | G46: 6 | I46: 6
E47: =E45/E46+G47+I47 -> 30829.052 | F47: =F45/F46+G47+I47 -> 48385.718 | G47: =G45/G46 -> 2645.7183 | I47: =I45/I46 -> 4500
D49: Воронцов | F49: ='май'!O6+'апрель'!O6+'март'!O6+'февраль'!N6+'январь'!N6+O7 -> 241126.7
F50: 6
F51: =F49/F50 -> 40187.783
D53: Калачев | E53: =33000+3000 -> 36000 | F53: =E9+E10+'май'!E8+'май'!E9+'май'!H8+'апрель'!E8+'апрель'!E9+'апрель'!H8+'март'!E8+'март'!E9+'февраль'!E8+'февраль'!E9+'январь'!E8+'январь'!E9 -> 407440 | G53: =G9+'май'!G8+'апрель'!G8+'март'!G8+'февраль'!G8+'январь'!G8 -> 48016.82
...

Sheet август
A2: Сервис партнер | B2: ФИО инженера | C2: подъездов/камер/домов | D2: ставка | E2: Оклад | F2: ГСМ | G2: Комиссия/Налоги | H2: Доп.работы | I2: покупка оборудования | J2: Оплата за монтажи кап вложения | K2: Оплата за монтажи сервис | L2: Оплата за монтажи модернизация | M2: ЭРТХА | N2: Удержание | O2: К выплате | P2: выплатили | Q2: доплата
A3: Самозанятый | B3: Садриев Ильдус | C3: 84 | D3: 100 | E3: =(C3*D3)+8800 -> 17200 | G3: 1282.26 | O3: =E3+F3+G3+H3+L3+M3-N3 -> 18482.26 | P3: запросила
A4: Самозанятый | B4: Нуретдинов Рафаэль (ВН) | E4: 10000 | G4: 638 | O4: =E4+F4+G4+H4+L4+M4-N4 -> 10638 | P4: запросила
A5: Самозанятый | B5: Касимов А. | C5: 499 | D5: 50 | E5: =24950+2500+4000 -> 31450 | G5: 2581.56 | K5: 3000 | O5: =E5+F5+G5+H5+L5+M5-N5+I5+J5+K5 -> 37031.56 | P5: запросила
A6: Самозанятый | B6: Богдан | C6: 333 | D6: 120 | E6: =39960+2500 -> 42460 | G6: 2937.6 | L6: =18000+3000 -> 21000 | O6: =E6+F6+G6+H6+L6+M6-N6+I6+J6 -> 66397.6 | P6: запросила
A7: Самозанятый | B7: Воронцов Денис | C7: 215 | D7: 147 | E7: =C7*D7 -> 31605 | G7: 2652.12 | H7: =5500+15000 -> 20500 | O7: =E7+F7+G7+H7+L7+M7-N7 -> 54757.12 | P7: запросила
A8: Самозанятый | B8: Диляра (КЦ) | E8: =15750+13000+2000+2088 -> 32838 | H8: =3750+2600+546 -> 6896
A9: Самозанятый | B9: Калачев Артем | C9: 645 | D9: 100.11 | E9: =645*100 -> 64500 | F9: 5500 | G9: 8492.7 | K9: =1000+500+4000+1500+6000 -> 13000 | L9: =30000 -> 30000 | O9: =E9+F9+E10+G9+H9+M9+N9+E8+H8+L9+K9 -> 163326.7 | P9: запросила
A10: Самозанятый | C10: 42 | D10: 50 | E10: =C10*D10 -> 2100
A11: Самозанятый | B11: Полуянов И. | C11: 351 | D11: 100 | E11: =C11*D11 -> 35100 | F11: 10000 | G11: 3158.52 | O11: =E11+E12+F11+G11+L11+H11+M11-N11 -> 52682.52 | P11: запросила
A12: Самозанятый | C12: 28 | D12: 158 | E12: =C12*D12 -> 4424
A13: Самозанятый | B13: Балашов Виталий | C13: 19 | D13: 800 | E13: =C13*D13 -> 15200 | G13: 15456 | H13: =400+800+1600+400+400+400+400+400+800+400+1000+800 -> 7800 | J13: =20000+24500+76500+38000+56000+3500 -> 218500 | O13: =E13+K13+G13+J13+H13 -> 256956
B14: Олег | E14: 30000 | H14: =500+500+1000 -> 2000 | O14: =E14+F14+G14+H14+M14-N14+I14 -> 32000
H15: =25300+500+500 -> 26300
B16: Илья | M16: =61756.2+3705.37 -> 65461.57 | O16: =M16+G16 -> 65461.57 | P16: запросила
B17: Костя | M17: =61756.2+3705.37 -> 65461.57 | O17: =M17+G17 -> 65461.57 | P17: запросила
B18: Гусейнов Артем | M18: 42800 | O18: =M18+G18 -> 42800 | P18: запросила
A19: ИТОГО | C19: =SUM(C3:C9) -> 1776 | E19: =SUM(E3:E17) -> 316877 | F19: =SUM(F3:F13) -> 15500 | G19: =SUM(G3:G17) -> 37198.76 | H19: =SUM(H3:H17) -> 63496 | I19: =SUM(I3:I18) -> 0 | J19: =SUM(J3:J18) -> 218500 | K19: =SUM(K3:K18) -> 16000 | L19: =SUM(L3:L18) -> 51000 | M19: =SUM(M3:M18) -> 173723.14 | N19: =SUM(N3:N13) -> 0 | O19: =SUM(O3:O18) -> 865994.9
D22: ФОТ | E22: =O19+'май'!O17+'апрель'!O17+'март'!O17+'февраль'!N17+'январь'!N17 -> 3983461.6
D24: МОНТАЖИ | E24: =J19+K19+L19+'май'!J17+'май'!K17+'май'!L17+'апрель'!L17+'март'!J17+'март'!L17+'февраль'!I17+'февраль'!J17+'февраль'!K17+'январь'!K17 -> 677200 | F24: 6 | G24: =E24/F24 -> 112866.67
D26: оборудование | E26: =I19+'март'!I17 -> 21500
D28: ФОТ за минусом | E28: =E22-E24-E26 -> 3284761.6 | F28: 6 | G28: =E28/F28 -> 547460.27
E31: =E22+E24+E26 -> 4682161.6 | F31: 6 | G31: =E31/F31 -> 780360.27
D34: Диляра | E34: =E8+'май'!E7+'апрель'!E7+'май'!H7+'март'!E7+'февраль'!E7+'январь'!E7 -> 199062 | F34: 6 | G34: =E34/F34 -> 33177
E36: ВН | F36: ДО | G36: Налог | H36: итого
D37: Ильдус | E37: =8000+8000+7200+7200+7200+72000 -> 109600 | F37: =840+840+840+840+840+840+6708 -> 11748 | G37: =G3+'май'!G3+'апрель'!G3+'март'!G3+'февраль'!G3+'январь'!G3/2 -> 7103.24
E38: 6 | F38: 6 | G38: 6
E39: =E37/E38+G39 -> 19450.54 | F39: =F37/F38 -> 1958 | G39: =G37/G38 -> 1183.8733
D41: Рафаэль | E41: =E4+'май'!E4+'апрель'!E4+'март'!E4+'февраль'!E4+'январь'!E4 -> 60000 | G41: =G4+'май'!G4+'апрель'!G4+'март'!G4+'февраль'!G4+'январь'!G4 -> 3829.58
E42: 6 | G42: 6
E43: =E41/E42+G43 -> 10638.263 | G43: =G41/G42 -> 638.26333
I44: Гараж+админ
D45: Касимов | E45: =22950+22950+23250+23250+24850+24850 -> 142100 | F45: =43800+43800+39960+39960+39960+39960 -> 247440 | G45: =(G5+'май'!G5+'апрель'!G5+'март'!G5+'февраль'!G5+'январь'!G5)/2 -> 16054.13 | I45: =54000/2 -> 27000
E46: 6 | F46: 6 | G46: 6 | I46: 6
E47: =E45/E46+G47+I47 -> 30859.022 | F47: =F45/F46+G47+I47 -> 48415.688 | G47: =G45/G46 -> 2675.6883 | I47: =I45/I46 -> 4500
D49: Воронцов | F49: ='май'!O6+'апрель'!O6+'март'!O6+'февраль'!N6+'январь'!N6+O7 -> 244993.4
F50: 6
F51: =F49/F50 -> 40832.233
D53: Калачев | E53: =33000+3000 -> 36000 | F53: =E9+E10+'май'!E8+'май'!E9+'май'!H8+'апрель'!E8+'апрель'!E9+'апрель'!H8+'март'!E8+'март'!E9+'февраль'!E8+'февраль'!E9+'январь'!E8+'январь'!E9 -> 407440 | G53: =G9+'май'!G8+'апрель'!G8+'март'!G8+'февраль'!G8+'январь'!G8 -> 46709.9
E54: 6 | F54: 6 | G54: 6
...

Sheet июль
A2: Сервис партнер | B2: ФИО инженера | C2: подъездов/камер/домов | D2: ставка | E2: Оклад | F2: ГСМ | G2: Комиссия/Налоги | H2: Доп.работы | I2: покупка оборудования | J2: Оплата за монтажи кап вложения | K2: Оплата за монтажи сервис | L2: Оплата за монтажи модернизация | M2: ЭРТХА | N2: Удержание | O2: К выплате | P2: выплатили | Q2: доплата
A3: Самозанятый | B3: Садриев Ильдус | C3: 84 | D3: 100 | E3: =(C3*D3)+8800 -> 17200 | G3: 971.28 | H3: 3200 | O3: =E3+F3+G3+H3+L3+M3-N3 -> 21371.28 | R3: 21371
A4: Самозанятый | B4: Нуретдинов Рафаэль (ВН) | E4: 10000 | G4: 636 | O4: =E4+F4+G4+H4+L4+M4-N4 -> 10636 | R4: 10636
A5: Самозанятый | B5: Касимов А. | C5: 499 | D5: 50 | E5: =24950+2500+4000 -> 31450 | G5: 8581.14 | J5: 3000 | O5: =E5+F5+G5+H5+L5+M5-N5+I5+J5 -> 43031.14 | R5: 42931
A6: Самозанятый | B6: Богдан | C6: 333 | D6: 120 | E6: =39960+2500 -> 42460 | G6: 0 | J6: =6000+500 -> 6500 | O6: =E6+F6+G6+H6+L6+M6-N6+I6+J6 -> 48960 | R6: 48960
A7: Самозанятый | B7: Воронцов Денис | C7: 215 | D7: 147 | E7: =C7*D7 -> 31605 | G7: 2097.48 | H7: =5000+5000+500 -> 10500 | O7: =E7+F7+G7+H7+L7+M7-N7 -> 44202.48 | R7: 44202
A8: Самозанятый | B8: Диляра (КЦ) | E8: =15750+10400+2000+2088 -> 30238
A9: Самозанятый | B9: Калачев Артем | C9: 645 | D9: 100.11 | E9: =645*100 -> 64500 | F9: 5500 | G9: 9207.12 | K9: 5000 | L9: =6000+24000 -> 30000 | O9: =E9+F9+E10+G9+H9+M9+L9-N9+E8 -> 141545.12 | R9: 106545
A10: Самозанятый | C10: 42 | D10: 50 | E10: =C10*D10 -> 2100
A11: Самозанятый | B11: Полуянов И. | C11: 351 | D11: 100 | E11: =C11*D11 -> 35100 | F11: 10000 | G11: 3117.96 | O11: =E11+E12+F11+G11+L11+H11+M11-N11 -> 52641.96 | P11: запросила чек | R11: 52642
A12: Самозанятый | C12: 28 | D12: 158 | E12: =C12*D12 -> 4424
A13: Самозанятый | B13: Балашов Виталий | C13: 18 | D13: 800 | E13: =C13*D13 -> 14400 | G13: 10873.6 | H13: 500 | J13: =40000+25000+10500+79500 -> 155000 | O13: =E13+K13+G13+J13+H13 -> 180773.6
B14: Олег | E14: 30000 | H14: =500+500+500+500 -> 2000 | I14: 17200 | O14: =E14+F14+G14+H14+M14-N14+I14 -> 49200
B15: Илья | M15: =61756.2+225+3718.87 -> 65700.07 | O15: =M15+G15 -> 65700.07 | R15: 65700
B16: Костя | M16: =61756.2+225+3718.87 -> 65700.07 | O16: =M16+G16 -> 65700.07 | R16: 65700
B17: Гусейнов Артем | M17: 42800 | O17: =M17+G17 -> 42800 | R17: 42800
A18: ИТОГО | C18: =SUM(C3:C9) -> 1776 | E18: =SUM(E3:E16) -> 313477 | F18: =SUM(F3:F13) -> 15500 | G18: =SUM(G3:G16) -> 35484.58 | H18: =SUM(H3:H16) -> 16200 | I18: =SUM(I3:I17) -> 17200 | J18: =SUM(J3:J17) -> 164500 | K18: =SUM(K3:K17) -> 5000 | L18: =SUM(L3:L17) -> 30000 | M18: =SUM(M3:M17) -> 174200.14 | N18: =SUM(N3:N13) -> 0 | O18: =SUM(O3:O17) -> 766561.72 | R18: =SUM(R3:R17) -> 501487
D21: ФОТ | E21: =O18+'май'!O17+'апрель'!O17+'март'!O17+'февраль'!N17+'январь'!N17 -> 3884028.4
D23: МОНТАЖИ | E23: =J18+K18+L18+'май'!J17+'май'!K17+'май'!L17+'апрель'!L17+'март'!J17+'март'!L17+'февраль'!I17+'февраль'!J17+'февраль'!K17+'январь'!K17 -> 591200 | F23: 6 | G23: =E23/F23 -> 98533.333
D25: оборудование | E25: =I18+'март'!I17 -> 38700
D27: ФОТ за минусом | E27: =E21-E23-E25 -> 3254128.4 | F27: 6 | G27: =E27/F27 -> 542354.74
E30: =E21+E23+E25 -> 4513928.4 | F30: 6 | G30: =E30/F30 -> 752321.41
D33: Диляра | E33: =E8+'май'!E7+'апрель'!E7+'май'!H7+'март'!E7+'февраль'!E7+'январь'!E7 -> 196462 | F33: 6 | G33: =E33/F33 -> 32743.667
E35: ВН | F35: ДО | G35: Налог | H35: итого
D36: Ильдус | E36: =8000+8000+7200+7200+7200+72000 -> 109600 | F36: =840+840+840+840+840+840+6708 -> 11748 | G36: =G3+'май'!G3+'апрель'!G3+'март'!G3+'февраль'!G3+'январь'!G3/2 -> 6792.26
E37: 6 | F37: 6 | G37: 6
E38: =E36/E37+G38 -> 19398.71 | F38: =F36/F37 -> 1958 | G38: =G36/G37 -> 1132.0433
D40: Рафаэль | E40: =E4+'май'!E4+'апрель'!E4+'март'!E4+'февраль'!E4+'январь'!E4 -> 60000 | G40: =G4+'май'!G4+'апрель'!G4+'март'!G4+'февраль'!G4+'январь'!G4 -> 3827.58
E41: 6 | G41: 6
E42: =E40/E41+G42 -> 10637.93 | G42: =G40/G41 -> 637.93
I43: Гараж+админ
D44: Касимов | E44: =22950+22950+23250+23250+24850+24850 -> 142100 | F44: =43800+43800+39960+39960+39960+39960 -> 247440 | G44: =(G5+'май'!G5+'апрель'!G5+'март'!G5+'февраль'!G5+'январь'!G5)/2 -> 19053.92 | I44: =54000/2 -> 27000
E45: 6 | F45: 6 | G45: 6 | I45: 6
E46: =E44/E45+G46+I46 -> 31358.987 | F46: =F44/F45+G46+I46 -> 48915.653 | G46: =G44/G45 -> 3175.6533 | I46: =I44/I45 -> 4500
D48: Воронцов | F48: ='май'!O6+'апрель'!O6+'март'!O6+'февраль'!N6+'январь'!N6+O7 -> 234438.76
F49: 6
F50: =F48/F49 -> 39073.127
D52: Калачев | E52: =33000+3000 -> 36000 | F52: =E9+E10+'май'!E8+'май'!E9+'май'!H8+'апрель'!E8+'апрель'!E9+'апрель'!H8+'март'!E8+'март'!E9+'февраль'!E8+'февраль'!E9+'январь'!E8+'январь'!E9 -> 407440 | G52: =G9+'май'!G8+'апрель'!G8+'март'!G8+'февраль'!G8+'январь'!G8 -> 47424.32
E53: 6 | F53: 6 | G53: 6
E54: =E52/E53 -> 6000 | F54: =F52/F53+G54 -> 75810.72 | G54: =G52/G53 -> 7904.0533
...

Sheet май
A2: Сервис партнер | B2: ФИО инженера | C2: подъездов/камер/домов | D2: ставка | E2: Оклад | F2: ГСМ | G2: Комиссия/Налоги | H2: Доп.работы | I2: покупка оборудования | J2: Оплата за монтажи кап вложения | K2: Оплата за монтажи сервис | L2: Оплата за монтажи модернизация | M2: ЭРТХА | N2: Удержание | O2: К выплате | P2: выплатили | Q2: доплата
A3: Самозанятый | B3: Садриев Ильдус | C3: 84 | D3: 100 | E3: =(C3*D3)+7200-800 -> 14800 | G3: 950 | O3: =E3+F3+H3+L3+M3-N3 -> 14800
A4: Самозанятый | B4: Нуретдинов Рафаэль (ВН) | E4: 10000 | G4: 638.28 | O4: =E4+F4+H4+L4+M4-N4 -> 10000
A5: Самозанятый | B5: Касимов А. | C5: 497/333 | D5: 50/120 | E5: =24850+39960+5000+4000 -> 73810 | G5: 5143 | J5: =48000+12000 -> 60000 | K5: 3000 | L5: 25000 | O5: =E5+F5+H5+L5+M5-N5+I5+J5+K5 -> 161810 | P5: 73810 | Q5: =161810-P5 -> 88000
A6: Самозанятый | B6: Воронцов Денис | C6: 215 | D6: 147 | E6: =C6*D6 -> 31605 | G6: 2110 | H6: 700 | O6: =E6+F6+G6+H6+L6+M6-N6+H7 -> 39215
A7: Самозанятый | B7: Диляра (КЦ) | E7: =11700+16500+2000+2232 -> 32432 | H7: 4800
A8: Самозанятый | B8: Калачев Артем | C8: 639 | D8: 100.11 | E8: =645*100 -> 64500 | F8: 5500 | G8: 8009 | H8: 790 | K8: =2000+2000+2700 -> 6700 | L8: =6000+12000+9000 -> 27000 | O8: =E8+F8+E9+H8+M8+L8-N8+E7+K8 -> 139022 | P8: 104532 | Q8: =139022-P8 -> 34490
A9: Самозанятый | C9: 42 | D9: 50 | E9: =C9*D9 -> 2100
A10: Самозанятый | B10: Полуянов И. | C10: 346 | D10: 100 | E10: =C10*D10 -> 34600 | F10: 10000 | G10: 3130 | O10: =E10+E11+F10+L10+H10+M10-N10 -> 49024 | P10: 49024
A11: Самозанятый | C11: 28 | D11: 158 | E11: =C11*D11 -> 4424
A12: Самозанятый | B12: Балашов Виталий | C12: 17 | D12: 800 | E12: =C12*D12 -> 13600 | G12: 1396 | H12: =2200+1500 -> 3700 | L12: 4500 | O12: =E12+H12+G12+L12 -> 23196
B13: Олег | E13: 30000 | H13: =500+750+500+500+500+800 -> 3550 | O13: =E13+F13+G13+H13+M13-N13 -> 33550
B14: Илья | M14: =61756.2+3705.37 -> 65461.57 | O14: =M14+G14 -> 65461.57
B15: Костя | M15: =61756.2+3705.37 -> 65461.57 | O15: =M15+G15 -> 65461.57
B16: Гусейнов Артем | M16: 42800 | O16: =M16+G16 -> 42800
A17: ИТОГО | C17: =SUM(C3:C8) -> 938 | E17: =SUM(E3:E15) -> 311871 | F17: =SUM(F3:F12) -> 15500 | G17: =SUM(G3:G15) -> 21376.28 | H17: =SUM(H3:H15) -> 13540 | I17: =SUM(I3:I16) -> 0 | J17: =SUM(J3:J16) -> 60000 | K17: =SUM(K3:K16) -> 9700 | L17: =SUM(L3:L16) -> 56500 | M17: =SUM(M3:M16) -> 173723.14 | N17: =SUM(N3:N12) -> 0 | O17: =SUM(O3:O16) -> 644340.14

Sheet июнь
A2: Сервис партнер | B2: ФИО инженера | C2: подъездов/камер/домов | D2: ставка | E2: Оклад | F2: ГСМ | G2: Комиссия/Налоги | H2: Доп.работы | I2: покупка оборудования | J2: Оплата за монтажи кап вложения | K2: Оплата за монтажи сервис | L2: Оплата за монтажи модернизация | M2: ЭРТХА | N2: Удержание | O2: К выплате | P2: выплатили | Q2: доплата
A3: Самозанятый | B3: Садриев Ильдус | C3: 84 | D3: 100 | E3: =(C3*D3)+7200-800 -> 14800 | G3: 888 | H3: 500 | O3: =E3+F3+G3+H3+L3+M3-N3 -> 16188 | P3: 16188
A4: Самозанятый | B4: Нуретдинов Рафаэль (ВН) | E4: 10000 | G4: 600 | O4: =E4+F4+G4+H4+L4+M4-N4 -> 10600 | P4: 10600
A5: Самозанятый | B5: Касимов А. | C5: 497/333 | D5: 50/120 | E5: =24850+39960+5000+4000 -> 73810 | G5: 9709 | H5: 2000 | J5: =35000+7500+15000 -> 57500 | O5: =E5+F5+G5+H5+L5+M5-N5+I5+J5 -> 143019 | P5: 85519 | Q5: 57500
A6: Самозанятый | B6: Воронцов Денис | C6: 215 | D6: 147 | E6: =C6*D6 -> 31605 | G6: 2353 | H6: 1000 | O6: =E6+F6+G6+H6+L6+M6-N6 -> 34958 | P6: 34958
A7: Самозанятый | B7: Диляра (КЦ) | E7: =13000+14250+2000+2160+2600 -> 34010
A8: Самозанятый | B8: Калачев Артем | C8: 639 | D8: 100.11 | E8: =645*100 -> 64500 | F8: 5500 | G8: 8342 | L8: =13*3000 -> 39000 | O8: =E8+F8+E9+G8+H8+M8+L8-N8+E7 -> 153452 | P8: 112052 | Q8: 39000 | R8: 2400 доплатили из кассы Диляре
A9: Самозанятый | C9: 42 | D9: 50 | E9: =C9*D9 -> 2100
A10: Самозанятый | B10: Полуянов И. | C10: 346 | D10: 100 | E10: =C10*D10 -> 34600 | F10: 10000 | G10: 2942 | O10: =E10+E11+F10+G10+L10+H10+M10-N10 -> 51966 | P10: 51966
A11: Самозанятый | C11: 28 | D11: 158 | E11: =C11*D11 -> 4424
A12: Самозанятый | B12: Балашов Виталий | C12: 17 | D12: 800 | E12: =C12*D12 -> 13600 | G12: 3546 | H12: =800+1000 -> 1800 | J12: 18000 | K12: =12000+10000 -> 22000 | O12: =E12+K12+G12+J12+H12 -> 58946
B13: Олег | E13: 30000 | H13: =500+500+2000+500+1000 -> 4500 | I13: =40000+2400 -> 42400 | O13: =E13+F13+G13+H13+M13-N13+I13 -> 76900
B14: Илья | M14: =61756.2+225+3718.87 -> 65700.07 | O14: =M14+G14 -> 65700.07
B15: Костя | M15: =61756.2+225+3718.87 -> 65700.07 | O15: =M15+G15 -> 65700.07
B16: Гусейнов Артем | M16: 42800 | O16: =M16+G16 -> 42800 | P16: 42800
A17: ИТОГО | C17: =SUM(C3:C8) -> 938 | E17: =SUM(E3:E15) -> 313449 | F17: =SUM(F3:F12) -> 15500 | G17: =SUM(G3:G15) -> 28380 | H17: =SUM(H3:H15) -> 9800 | I17: =SUM(I3:I16) -> 42400 | J17: =SUM(J3:J16) -> 75500 | K17: =SUM(K3:K16) -> 22000 | L17: =SUM(L3:L16) -> 39000 | M17: =SUM(M3:M16) -> 174200.14 | N17: =SUM(N3:N12) -> 0 | O17: =SUM(O3:O16) -> 720229.14
D20: ФОТ | E20: =O17+'май'!O17+'апрель'!O17+'март'!O17+'февраль'!N17+'январь'!N17 -> 3837695.9
D22: МОНТАЖИ | E22: =J17+K17+L17+'май'!J17+'май'!K17+'май'!L17+'апрель'!L17+'март'!J17+'март'!L17+'февраль'!I17+'февраль'!J17+'февраль'!K17+'январь'!K17 -> 528200 | F22: 6 | G22: =E22/F22 -> 88033.333
J23: ='январь'!E7+'февраль'!E7+'март'!E7+'апрель'!E7+'май'!E7+E7 -> 195434
D24: оборудование | E24: =I17+'март'!I17 -> 63900
D26: ФОТ за минусом | E26: =E20-E22-E24 -> 3245595.9 | F26: 6 | G26: =E26/F26 -> 540932.64
E29: =E20+E22+E24 -> 4429795.9 | F29: 6 | G29: =E29/F29 -> 738299.31
D32: Диляра | E32: =E7+'май'!E7+'апрель'!E7+'май'!H7+'март'!E7+'февраль'!E7+'январь'!E7 -> 200234 | F32: 6 | G32: =E32/F32 -> 33372.333
E34: ВН | F34: ДО | G34: Налог | H34: итого
D35: Ильдус | E35: =8000+8000+7200+7200+7200+72000 -> 109600 | F35: =840+840+840+840+840+840+6708 -> 11748 | G35: =G3+'май'!G3+'апрель'!G3+'март'!G3+'февраль'!G3+'январь'!G3/2 -> 6708.98
E36: 6 | F36: 6 | G36: 6
E37: =E35/E36+G37 -> 19384.83 | F37: =F35/F36 -> 1958 | G37: =G35/G36 -> 1118.1633
D39: Рафаэль | E39: =E4+'май'!E4+'апрель'!E4+'март'!E4+'февраль'!E4+'январь'!E4 -> 60000 | G39: =G4+'май'!G4+'апрель'!G4+'март'!G4+'февраль'!G4+'январь'!G4 -> 3791.58
E40: 6 | G40: 6
E41: =E39/E40+G41 -> 10631.93 | G41: =G39/G40 -> 631.93
I42: Гараж+админ
D43: Касимов | E43: =22950+22950+23250+23250+24850+24850 -> 142100 | F43: =43800+43800+39960+39960+39960+39960 -> 247440 | G43: =(G5+'май'!G5+'апрель'!G5+'март'!G5+'февраль'!G5+'январь'!G5)/2 -> 19617.85 | I43: =54000/2 -> 27000
E44: 6 | F44: 6 | G44: 6 | I44: 6
E45: =E43/E44+G45+I45 -> 31452.975 | F45: =F43/F44+G45+I45 -> 49009.642 | G45: =G43/G44 -> 3269.6417 | I45: =I43/I44 -> 4500
D47: Воронцов | F47: ='май'!O6+'апрель'!O6+'март'!O6+'февраль'!N6+'январь'!N6+O6 -> 225194.28
F48: 6
F49: =F47/F48 -> 37532.38
D51: Калачев | E51: =33000+3000 -> 36000 | F51: =E8+E9+'май'!E8+'май'!E9+'май'!H8+'апрель'!E8+'апрель'!E9+'апрель'!H8+'март'!E8+'март'!E9+'февраль'!E8+'февраль'!E9+'январь'!E8+'январь'!E9 -> 407440 | G51: =G8+'май'!G8+'апрель'!G8+'март'!G8+'февраль'!G8+'январь'!G8 -> 46559.2
E52: 6 | F52: 6 | G52: 6
E53: =E51/E52 -> 6000 | F53: =F51/F52+G53 -> 75666.533 | G53: =G51/G52 -> 7759.8667
...

Sheet апрель
A2: Сервис партнер | B2: ФИО инженера | C2: подъездов/камер/домов | D2: ставка | E2: Оклад | F2: ГСМ | G2: Комиссия/Налоги | H2: Доп.работы | I2: покупка оборудования | J2: Оплата за монтажи кап вложения | K2: Оплата за монтажи сервис | L2: Оплата за монтажи модернизация | M2: ЭРТХА | N2: Удержание | O2: К выплате | P2: выплатили | Q2: доплата
A3: Самозанятый | B3: Садриев Ильдус | C3: 84 | D3: 100 | E3: =(C3*D3)+7200-800 -> 14800 | G3: 1017.66 | O3: =E3+F3+G3+H3+L3+M3-N3 -> 15817.66
A4: Самозанятый | B4: Нуретдинов Рафаэль (ВН) | E4: 10000 | G4: 638.28 | O4: =E4+F4+G4+H4+L4+M4-N4 -> 10638.28
A5: Самозанятый | B5: Касимов А. | C5: 465/333 | D5: 50/120 | E5: =23250+39960+5000+4000 -> 72210 | G5: 13498.32 | O5: =E5+F5+G5+H5+L5+M5-N5+I5+J5 -> 85708.32
A6: Самозанятый | B6: Воронцов Денис | C6: 215 | D6: 147 | E6: =C6*D6 -> 31605 | G6: 2147.34 | H6: =700+700 -> 1400 | O6: =E6+F6+G6+H6+L6+M6-N6 -> 35152.34
A7: Самозанятый | B7: Диляра (КЦ) | E7: =10400+16500+2000+2232 -> 31132
A8: Самозанятый | B8: Калачев Артем | C8: 639 | D8: 100.11 | E8: =645*100 -> 64500 | F8: 5500 | G8: 8751.3 | H8: 6500 | L8: 15000 | O8: =E8+F8+E9+G8+H8+M8+L8-N8+E7 -> 133483.3
A9: Самозанятый | C9: 42 | D9: 50 | E9: =C9*D9 -> 2100
A10: Самозанятый | B10: Полуянов И. | C10: 346 | D10: 100 | E10: =C10*D10 -> 34600 | F10: 10000 | G10: 3130.08 | O10: =E10+E11+F10+G10+L10+H10+M10-N10 -> 52154.08
A11: Самозанятый | C11: 28 | D11: 158 | E11: =C11*D11 -> 4424
A12: Самозанятый | B12: Балашов Виталий | C12: 17 | D12: 800 | E12: =C12*D12 -> 13600 | G12: 1690 | H12: =10000+800+2000 -> 12800 | O12: =E12+H12+G12 -> 28090
B13: Олег | E13: 30000 | H13: =500+500+500 -> 1500 | O13: =E13+F13+G13+H13+M13-N13 -> 31500
B14: Илья | M14: =61756.2+75+3709.87 -> 65541.07 | O14: =M14+G14 -> 65541.07
B15: Костя | M15: =61756.2+75+3709.87 -> 65541.07 | O15: =M15+G15 -> 65541.07
B16: Гусейнов Артем | M16: 42800 | O16: =M16+G16 -> 42800
A17: ИТОГО | C17: =SUM(C3:C8) -> 938 | E17: =SUM(E3:E15) -> 308971 | F17: =SUM(F3:F12) -> 15500 | G17: =SUM(G3:G15) -> 30872.98 | H17: =SUM(H3:H15) -> 22200 | I17: =SUM(I3:I16) -> 0 | J17: =SUM(J3:J16) -> 0 | K17: =SUM(K3:K16) -> 0 | L17: =SUM(L3:L16) -> 15000 | M17: =SUM(M3:M16) -> 173882.14 | N17: =SUM(N3:N12) -> 0 | O17: =SUM(O3:O16) -> 566426.12

Sheet март
A2: Сервис партнер | B2: ФИО инженера | C2: подъездов/камер/домов | D2: ставка | E2: Оклад | F2: ГСМ | G2: Комиссия/Налоги | H2: Доп.работы | I2: покупка оборудования | J2: Оплата за монтажи кап вложения | K2: Оплата за монтажи сервис | L2: Оплата за монтажи модернизация | M2: ЭРТХА | N2: Удержание | O2: К выплате | P2: выплатили | Q2: доплата
A3: Самозанятый | B3: Садриев Ильдус | C3: 84 | D3: 100 | E3: =(C3*D3)+7200-800 -> 14800 | G3: 2160.78 | O3: =E3+F3+G3+H3+L3+M3-N3 -> 16960.78 | P3: 16961 | Q3: 0
A4: Самозанятый | B4: Нуретдинов Рафаэль (ВН) | E4: 10000 | G4: 638.28 | O4: =E4+F4+G4+H4+L4+M4-N4 -> 10638.28 | P4: 10638 | Q4: 0
A5: Самозанятый | B5: Касимов А. | C5: 465/333 | D5: 50/120 | E5: =23250+39960+5000+4000 -> 72210 | G5: 6262.38 | H5: 1500 | I5: =2000+14000 -> 16000 | J5: =9000+120000 -> 129000 | O5: =E5+F5+G5+H5+L5+M5-N5+I5+J5 -> 224972.38 | P5: =O5-Q5 -> 78472.38 | Q5: 146500
A6: Самозанятый | B6: Воронцов Денис | C6: 215 | D6: 147 | E6: =C6*D6 -> 31605 | G6: 2083.56 | H6: =1500+300+300 -> 2100 | O6: =E6+F6+G6+H6+L6+M6-N6 -> 35788.56 | P6: 35789 | Q6: 0
A7: Самозанятый | B7: Диляра (КЦ) | E7: =13000+15750+2000+2201 -> 32951 | P7: 0 | Q7: 0
A8: Самозанятый | B8: Калачев Артем | C8: 645 | D8: 100.11 | E8: =645*100 -> 64500 | F8: 5500 | G8: 7803.78 | H8: 3000 | L8: =3000*10 -> 30000 | O8: =E8+F8+E9+G8+H8+M8+L8-N8+E7 -> 145854.78 | P8: =O8-Q8 -> 112854.78 | Q8: 33000
A9: Самозанятый | C9: 42 | D9: 50 | E9: =C9*D9 -> 2100
A10: Самозанятый | B10: Полуянов И. | C10: 346 | D10: 100 | E10: =C10*D10 -> 34600 | F10: 10000 | G10: 3143.82 | O10: =E10+E11+F10+G10+L10+H10+M10-N10 -> 52167.82 | P10: 52168 | Q10: 0
A11: Самозанятый | C11: 28 | D11: 158 | E11: =C11*D11 -> 4424
A12: Самозанятый | B12: Балашов Виталий | C12: 17 | D12: 800 | E12: =C12*D12 -> 13600 | G12: 1811.2 | H12: =1200+1000+2000+400+1000+1600+2000 -> 9200 | I12: 5500 | O12: =E12+H12+G12+I12 -> 30111.2 | P12: 30111 | Q12: 0
B13: Олег | E13: 30000 | H13: 3500 | O13: =E13+F13+G13+H13+M13-N13 -> 33500 | P13: 33500 | Q13: 0
B14: Илья | M14: =61756.2+75+3709.87 -> 65541.07 | O14: =M14+G14 -> 65541.07
B15: Костя | M15: =61756.2+75+3709.87 -> 65541.07 | O15: =M15+G15 -> 65541.07 | P15: 65541 | Q15: 0
B16: Гусейнов Артем | M16: 42800 | O16: =M16+G16 -> 42800 | P16: 42800 | Q16: 0
A17: ИТОГО | C17: =SUM(C3:C8) -> 944 | E17: =SUM(E3:E15) -> 310790 | F17: =SUM(F3:F12) -> 15500 | G17: =SUM(G3:G15) -> 23903.8 | H17: =SUM(H3:H15) -> 19300 | I17: =SUM(I3:I16) -> 21500 | J17: =SUM(J3:J16) -> 129000 | K17: =SUM(K3:K16) -> 0 | L17: =SUM(L3:L16) -> 30000 | M17: =SUM(M3:M16) -> 173882.14 | N17: =SUM(N3:N12) -> 0 | O17: =SUM(O3:O16) -> 723875.94

Sheet февраль
A2: Сервис партнер | B2: ФИО инженера | C2: подъездов/камер/домов | D2: ставка | E2: Оклад | F2: ГСМ | G2: Комиссия/Налоги | H2: Доп.работы | I2: Оплата за монтажи кап вложения | J2: Оплата за монтажи модернизация | K2: Оплата за монтажи сервис | L2: ЭРТХА | M2: Удержание | N2: К выплате
A3: Самозанятый | B3: Садриев Ильдус | C3: 84 | D3: 100 | E3: =C3*D3+8000 -> 16400 | G3: 1113.48 | I3: 16500 | K3: 2000 | N3: =E3+F3+G3+K3+I3+L3-M3 -> 36013.48
A4: Самозанятый | B4: Нуретдинов Рафаэль (ВН) | E4: 10000 | G4: 638.28 | N4: =E4+F4+G4+H4+K4+L4-M4 -> 10638.28
A5: Самозанятый | B5: Касимов А. | C5: 459/365 | D5: 50/120 | E5: =22950+43800+5000+4000 -> 75750 | G5: 4623 | I5: =3000+9000+9000 -> 21000 | K5: 3000 | N5: =E5+F5+G5+K5+I5+L5-M5 -> 104373
A6: Самозанятый | B6: Воронцов Денис | C6: 215 | D6: 147 | E6: =C6*D6 -> 31605 | G6: 2721.24 | H6: 400 | N6: =E6+F6+G6+H6+K6+L6-M6 -> 34726.24
A7: Самозанятый | B7: Диляра (КЦ) | E7: 29388
A8: Самозанятый | B8: Калачев Артем | C8: 645 | D8: 100.11 | E8: =645*100 -> 64500 | F8: 5500 | G8: 7574.94 | J8: 21000 | N8: =E8+F8+E9+G8+H8+L8+K8-M8+E7+J8 -> 130062.94
A9: Самозанятый | C9: 42 | D9: 50 | E9: =C9*D9 -> 2100
A10: Самозанятый | B10: Полуянов И. | C10: 346 | D10: 100 | E10: =C10*D10 -> 34600 | F10: 10000 | G10: 3373.26 | N10: =E10+E11+F10+G10+K10+H10+L10-M10 -> 52397.26
A11: Самозанятый | C11: 28 | D11: 158 | E11: =C11*D11 -> 4424
A12: Самозанятый | B12: Балашов Виталий | C12: 16 | D12: 800 | E12: =16*800 -> 12800 | H12: =117+1000+400+400+2083.84 -> 4000.84 | I12: 16000 | N12: =E12+H12+I12 -> 32800.84
B13: Олег | E13: 30000 | N13: =E13+F13+G13+H13+L13-M13 -> 30000
B14: Илья | L14: 65726.57 | N14: =L14+G14 -> 65726.57
B15: Костя | L15: 65726.57 | N15: =L15+G15 -> 65726.57
B16: Гусейнов Артем | L16: 42800 | N16: =L16+G16 -> 42800
A17: ИТОГО | C17: =SUM(C3:C8) -> 944 | E17: =SUM(E3:E15) -> 311567 | F17: =SUM(F3:F12) -> 15500 | G17: =SUM(G3:G15) -> 20044.2 | H17: =SUM(H3:H15) -> 4400.84 | I17: =SUM(I3:I16) -> 53500 | J17: =SUM(J3:J16) -> 21000 | K17: =SUM(K3:K15) -> 5000 | L17: =SUM(L3:L16) -> 174253.14 | M17: =SUM(M3:M12) -> 0 | N17: =SUM(N3:N16) -> 605265.18

Sheet январь
A2: Сервис партнер | B2: ФИО инженера | C2: подъездов/камер/домов | D2: ставка | E2: Оклад | F2: ГСМ | G2: Комиссия/Налоги | H2: Доп.работы | I2: Оплата за монтажи сервис | J2: Оплата за монтажи кап вложения | K2: Оплата за монтажи Модернизация | L2: ЭРТХА | M2: Удержание | N2: К выплате | O2: Налог с чека января
A3: Самозанятый | B3: Садриев Ильдус | C3: 84 | D3: 100 | E3: =C3*D3+8000 -> 16400 | G3: =1158.12 -> 1158.12 | H3: 1000 | N3: =E3+F3+G3+H3+K3+L3-M3 -> 18558.12 | O3: 1053.48
A4: Самозанятый | B4: Нуретдинов Рафаэль (ВН) | E4: 10000 | G4: 638.46 | N4: =E4+F4+G4+H4+K4+L4-M4 -> 10638.46 | O4: 638.28
A5: Самозанятый | B5: Касимов А.(ВН) | C5: 459/365 | D5: 50/120 | E5: =22950+43800+5000+4000 -> 75750 | G5: 0 | H5: =800+500 -> 1300 | N5: =E5+F5+G5+H5+K5+L5-M5 -> 77050
A6: Самозанятый | B6: Воронцов Денис | C6: 215 | D6: 147 | E6: =C6*D6 -> 31605 | G6: 5449.14 | H6: =1700+1000+3600+2000 -> 8300 | N6: =E6+F6+G6+H6+K6+L6-M6 -> 45354.14
A7: Самозанятый | B7: Диляра (КЦ) | E7: 35521
A8: Самозанятый | B8: Калачев Артем | C8: 650 | D8: 100.11 | E8: =650*100 -> 65000 | F8: 5500 | G8: 6078.18 | K8: =4*3000 -> 12000 | N8: =E8+F8+E9+G8+H8+L8+K8-M8+E7 -> 126249.18
A9: Самозанятый | C9: 43 | D9: 50 | E9: =C9*D9 -> 2150
A10: Самозанятый | B10: Полуянов И. | C10: 347 | D10: 100 | E10: =C10*D10 -> 34700 | F10: 10000 | G10: =3297.18+3800.26 -> 7097.44 | N10: =E10+E11+F10+G10+K10+H10+L10-M10 -> 56221.44
A11: Самозанятый | C11: 28 | D11: 158 | E11: =C11*D11 -> 4424
A12: Самозанятый | B12: Балашов Виталий | E12: 27600 | N12: =E12+H12 -> 27600
B13: Олег | E13: 30000 | H13: =2*300 -> 600 | N13: =E13+F13+G13+H13+L13-M13 -> 30600
B14: Илья | L14: =71194+50 -> 71244 | N14: =L14+G14 -> 71244
B15: Костя | L15: =71194+50 -> 71244 | N15: =L15+G15 -> 71244
B16: Гусейнов Артем | L16: 42800 | N16: =L16+G16 -> 42800
A17: ИТОГО | C17: =SUM(C3:C8) -> 949 | E17: =SUM(E3:E15) -> 333150 | F17: =SUM(F3:F12) -> 15500 | G17: =SUM(G3:G15) -> 20421.34 | H17: =SUM(H3:H15) -> 11200 | I17: =SUM(I3:I16) -> 0 | J17: =SUM(J3:J16) -> 0 | K17: =SUM(K3:K15) -> 12000 | L17: =SUM(L3:L16) -> 185288 | M17: =SUM(M3:M12) -> 0 | N17: =SUM(N3:N16) -> 577559.34 | O17: =N17 -> 577559.34
N18: 5000 | O18: Позитив
N19: 27600 | O19: Ключи
N20: 32600

Sheet Итого
B1: ФОТ оклад | C1: ФОТ кап вложения | D1: ФОТ Сервис | E1: ФОТ Модернизация | F1: оборудование | G1: общая | J1: вн за год
A2: Садриев Ильдус | B2: ='январь'!N3+'февраль'!E3+'февраль'!G3+'март'!O3+'апрель'!O3+'май'!O3+'июнь'!O3+'июль'!O3+'август'!O3+'сентябрь'!O3+'октябрь'!O3+'ноябрь'!O3+'декабрь'!O3 -> 226523.74 | C2: ='февраль'!I3 -> 16500 | D2: ='февраль'!K3 -> 2000 | G2: ='январь'!N3+'февраль'!N3+'март'!O3+'апрель'!O3+'май'!O3+'июнь'!O3+'июль'!O3+'август'!O3+'сентябрь'!O3+'октябрь'!O3+'ноябрь'!O3+'декабрь'!O3 -> 245023.74 | H2: =B2+C2+D2+F2+E2 -> 245023.74 | I2: =H2-G2 -> 0 | J2: 112500 | K2: =G2-J2-D2 -> 130523.74
A3: Нуретдинов Рафаэль (ВН) | B3: ='январь'!N4+'февраль'!N4+'март'!O4+'апрель'!O4+'май'!O4+'июнь'!O4+'июль'!O4+'август'!O4+'сентябрь'!O4+'октябрь'!O4+'ноябрь'!O4+'декабрь'!O4 -> 126980.42 | G3: ='январь'!N4+'февраль'!N4+'март'!O4+'апрель'!O4+'май'!O4+'июнь'!O4+'июль'!O4+'август'!O4+'сентябрь'!O4+'октябрь'!O4+'ноябрь'!O4+'декабрь'!O4 -> 126980.42 | H3: =B3+C3+D3+F3+E3 -> 126980.42 | I3: =H3-G3 -> 0
A4: Касимов А.(ВН) | B4: ='январь'!N5+'февраль'!E5+'февраль'!G5+'март'!E5+'март'!G5+'март'!H5+'апрель'!E5+'апрель'!G5+'май'!E5+'июнь'!E5+'июнь'!G5+'июнь'!H5+'июль'!E5+'июль'!G5+'август'!E5+'август'!G5+'сентябрь'!E5+'сентябрь'!G5+'октябрь'!E5+'октябрь'!G5+'ноябрь'!E5+'ноябрь'!G5+'декабрь'!E12+'декабрь'!G12 -> 695980.74 | C4: ='февраль'!I5+'март'!J5+'май'!J5+'июнь'!J5+'июль'!J5 -> 270500 | D4: ='февраль'!K5+'май'!K5+'август'!K5 -> 9000 | E4: ='май'!L5+'декабрь'!L12 -> 82000 | F4: ='март'!I5 -> 16000 | G4: ='январь'!N5+'февраль'!N5+'март'!O5+'апрель'!O5+'май'!O5+'июнь'!O5+'июль'!O5+'август'!O5+'сентябрь'!O5+'октябрь'!O5+'ноябрь'!O5+'декабрь'!O12 -> 1073480.7 | H4: =B4+C4+D4+F4+E4 -> 1073480.7 | I4: =H4-G4 -> 4.6566129e-10 | J4: =G4-C4-D4-E4-F4 -> 695980.74
A5: Воронцов Денис | B5: ='январь'!N6+'февраль'!N6+'март'!O6+'апрель'!O6+'июль'!E7+'июль'!G7+'июль'!H7+'август'!O7+'сентябрь'!E7+'сентябрь'!G7+'сентябрь'!H7+'октябрь'!E7+'октябрь'!G7+'ноябрь'!O7+'декабрь'!O13+'июнь'!O6+'май'!E6+'май'!G6+'май'!H6 -> 480420.04 | D5: ='октябрь'!K7 | E5: ='октябрь'!L7 -> 10000 | F5: ='июль'!I7+'сентябрь'!I7+'октябрь'!I7 -> 2500 | G5: ='декабрь'!O13+'ноябрь'!O7+'октябрь'!O7+'сентябрь'!O7+'август'!O7+'июль'!O7+'июнь'!O6+'май'!O6+'апрель'!O6+'март'!O6+'февраль'!N6+'январь'!N6 -> 497720.04 | H5: =B5+C5+D5+F5+E5 -> 492920.04 | I5: =H5-G5 -> -4800 | K5: =H5-F5-E5 -> 480420.04
A6: Васильев | B6: ='июль'!E6+'август'!G6+'август'!E6+'сентябрь'!G6+'сентябрь'!E6+'октябрь'!E6+'октябрь'!G6+'ноябрь'!E6+'ноябрь'!G6+'декабрь'!O5 -> 278296.78 | C6: ='июль'!J6 -> 6500 | D6: ='сентябрь'!K6+'октябрь'!K6 -> 13200 | E6: ='август'!L6+'ноябрь'!L6 -> 55500 | G6: =B6+C6+D6+E6+F6 -> 353496.78 | H6: =B6+C6+D6+F6+E6 -> 353496.78 | I6: =H6-G6 -> 0 | J6: =G6-E6-D6-C6 -> 278296.78
A7: Диляра (КЦ) | B7: ='январь'!E7+'февраль'!E7+'март'!E7+'апрель'!E7+'май'!E7+'май'!H7+'июнь'!E7+'июль'!E8+'август'!E8+'сентябрь'!E8+'октябрь'!E8+'ноябрь'!E8+'декабрь'!E6 -> 394726 | G7: =B7+C7+D7+E7+F7 -> 394726 | H7: =B7+C7+D7+F7+E7 -> 394726 | I7: =H7-G7 -> 0
A8: Калачев Артем | B8: ='январь'!E8+'январь'!E9+'январь'!F8+'январь'!G8+'февраль'!E8+'февраль'!E9+'февраль'!F8+'февраль'!G8+'март'!E8+'март'!E9+'март'!F8+'март'!G8+'март'!H8+'апрель'!E8+'апрель'!E9+'апрель'!F8+'апрель'!G8+'апрель'!H8+'май'!E8+'май'!E9+'май'!F8+'май'!H8+'июнь'!E8+'июнь'!E9+'июнь'!F8+'июнь'!G8+'июль'!E9+'июль'!E10+'июль'!F9+'июль'!G9+'август'!E9+'август'!E10+'август'!F9+'август'!G9+'сентябрь'!E9+'сентябрь'!E10+'сентябрь'!F9+'сентябрь'!G9+'сентябрь'!H9+'октябрь'!E9+'октябрь'!E10+'октябрь'!F9+'октябрь'!G9+'ноябрь'!E9+'ноябрь'!E10+'ноябрь'!F9+'ноябрь'!G9+'декабрь'!E7+'декабрь'!E8+'декабрь'!F7+'декабрь'!G7+'декабрь'!H7+'май'!G8 -> 993251.02 | D8: ='май'!K8+'июль'!K9+'август'!K9 -> 24700 | E8: ='январь'!K8+'февраль'!J8+'март'!L8+'апрель'!L8+'май'!L8+'июнь'!L8+'июль'!L9+'август'!L9+'сентябрь'!L9+'ноябрь'!L9+'декабрь'!L7 -> 276000 | G8: ='январь'!N8+'февраль'!N8+'март'!O8+'апрель'!O8+'май'!O8+'июнь'!O8+'июль'!O9+'август'!O9+'сентябрь'!O9+'октябрь'!O9+'ноябрь'!O9+'декабрь'!O7 -> 1677764 | H8: =B8+C8+D8+F8+E8 -> 1293951 | I8: =H8-G8 -> -383813 | J8: =H8+G7 -> 1688677 | K8: =G8-J8 -> -10913 | L8: =B8-66000-25200 -> 902051.02
A9: Полуянов И. | G9: =B9+C9+D9+E9+F9 -> 0 | H9: =B9+C9+D9+F9+E9 -> 0 | I9: =H9-G9 -> 0 | K9: 2400 диляры из кассы | L9: 8009 отд чек на налог
B10: ='январь'!N10+'февраль'!N10+'март'!O10+'апрель'!O10+'май'!O10+'июнь'!O10+'июль'!O11+'август'!O11+'сентябрь'!O11+'октябрь'!O11+'ноябрь'!O11+'декабрь'!O9 -> 637617.82 | G10: =B10+C10+D10+E10+F10 -> 637617.82 | H10: =B10+C10+D10+F10+E10 -> 637617.82 | I10: =H10-G10 -> 0
A11: Балашов Виталий | B11: ='январь'!E12+'февраль'!E12+'февраль'!H12+'март'!E12+'март'!G12+'март'!H12+'апрель'!E12+'апрель'!G12+'апрель'!H12+'май'!E12+'май'!G12+'май'!H12+'июнь'!E12+'июнь'!G12+'июнь'!H12+'июль'!E13+'июль'!G13+'июль'!H13+'август'!E13+'август'!G13+'август'!H13+'сентябрь'!E13+'сентябрь'!G13+'октябрь'!E13+'октябрь'!G13+'ноябрь'!E13+'ноябрь'!H13+'декабрь'!E14+'декабрь'!G14+'декабрь'!H14 -> 305868.04 | C11: ='февраль'!I12+'июнь'!J12+'июль'!J13+'август'!J13+'сентябрь'!J13+'октябрь'!J13+'ноябрь'!J13+'декабрь'!J14 -> 916500 | D11: ='июнь'!K12+'сентябрь'!K13+'октябрь'!K13 -> 41300 | E11: ='май'!L12 -> 4500 | F11: ='март'!I12 -> 5500 | G11: ='январь'!N12+'февраль'!N12+'март'!O12+'апрель'!O12+'май'!O12+'июнь'!O12+'июль'!O13+'август'!O13+'сентябрь'!O13+'октябрь'!O13+'ноябрь'!O13+'декабрь'!O14 -> 1273668 | H11: =B11+C11+D11+F11+E11 -> 1273668 | I11: =H11-G11 -> 0
A12: Олег | B12: ='январь'!N13+'февраль'!N13+'март'!O13+'апрель'!O13+'май'!O13+'июнь'!E13+'июнь'!H13+'июль'!E14+'июль'!H14+'август'!E14+'август'!H14+'сентябрь'!E14+'сентябрь'!H14+'октябрь'!O14+'ноябрь'!O14+'декабрь'!O15 -> 385610 | F12: ='июнь'!I13+'июль'!I14 -> 59600 | G12: ='январь'!N13+'февраль'!N13+'март'!O13+'апрель'!O13+'май'!O13+'июнь'!O13+'июль'!O14+'август'!O14+'сентябрь'!O14+'октябрь'!O14+'ноябрь'!O14+'декабрь'!O15 -> 445210 | H12: =B12+C12+D12+F12+E12 -> 445210 | I12: =H12-G12 -> 0 | J12: 402810

Sheet Касимов
B1: Кол-во | C1: Цена
A2: Камеры | B2: 459 | C2: 50 | D2: =B2*C2 -> 22950
A3: Подъезды | B3: 365 | C3: 120 | D3: =B3*C3 -> 43800
A4: Налог | D4: 5718.36
D5: =SUM(D2:D4) -> 72468.36

Sheet Мониторинг
B1: Кол-во на 31.03.25 | D1: на 30.06.25 | E1: на 30.09.25
B2: Камеры | C2: 769 | D2: 859 | E2: 905
B3: Домофоны | C3: 421 | D3: 448 | E3: 556
B4: Итого | C4: =SUM(C2:C3) -> 1190 | D4: =SUM(D2:D3) -> 1307 | E4: =SUM(E2:E3) -> 1461
B6: Первоночальный расчет
B7: Кол-во | C7: Цена | D7: Стоимость одной камеры | E7: кол-во дней
A8: Было в 2024 го | B8: 1085 | C8: 4000 | D8: =C8/B8 -> 3.6866359
A9: На 31.03.25 | B9: =C4 -> 1190 | E9: 31 | F9: 2
A10: Добавилось | B10: =B9-B8 -> 105 | C10: =B10*D8 -> 387.09677 | D10: =C8+C10 -> 4387.0968 | E10: =D10/E9 -> 141.51925 | F10: =E10/F9 -> 70.759625 | G10: за 1 день день
A11: Добавилось за 1 кв | B11: =4+13 -> 17 | C11: =B11*D8 -> 62.672811 | D11: 4453.83
A12: Добавка за 9 мес. | B12: 154 | C12: =B12*D8 -> 567.74194 | D12: =D10+C12 -> 4954.8387 | E12: =D12/E9 -> 159.83351 | F12: =E12/F9 -> 79.916753 | G12: за 1 день день
A16: мониторинг (как делали расчет)
A17: взяли 4000 руб. / 30 дней =133 / 2 (человека) = 66,66 день
A18: Альм - 434
A19: Зел - 118
A20: Тюм - 60
A21: Инно - 103
A22: Зел. - 15
A23: Панели - 355
A26: Всего 1085 шт
A28: 2 кв | B28: спутники | C28: камеры
A29: Тюмень

Sheet Девочки
J1: Если тебе надо 100 на руки то 100/90.5*100=110497.
A2: Наташа за январь 2025 | D2: Анна за январь 2025 | G2: Я за январь 2025
A3: ЗП на руки | B3: 32000 | D3: ЗП на руки | E3: =35000+3000+3500 -> 41500 | G3: ЗП на руки | H3: 10000
A4: ЗП аванс | B4: 10001.55 | D4: ЗП аванс | E4: 10062.13 | G4: Мониторинг, 6 дн | H4: =6*71 -> 426
A5: ЗП первичка | B5: 10000.25 | D5: ЗП первичка | E5: 10062.12 | G5: Звонки будни | H5: 3750
A6: ЗП вторчка | B6: =B3-B4-B5 -> 11998.2 | D6: ЗП вторчка | E6: =E3-E4-E5 -> 21375.75 | G6: 1 с | H6: 7500
A7: Мониторинг, 17 дн | B7: =17*71 -> 1207 | D7: ЭРТХА
D8: прием звонков 03.02. | E8: 750
A9: Итого | B9: =B6+B7 -> 13205.2 | G9: Итого | H9: =SUM(H3:H8) -> 21676 | J9: =B9+E10+H9 -> 57006.95 | L9: =E10+H9+E21+H20+E32+H30+E44+H42+E54+H54+E68+H66+E85+H83+E97+H95+E108+H107+E120+H118+E133+H131+E144+H143 -> 540052.54
D10: Итого | E10: =E6+E7+E8 -> 22125.75
A13: Наташа за февраль 2025 | D13: Анна за февраль 2025 | G13: Я за февраль 2025
A14: ЗП на руки | B14: 32000 | D14: ЗП на руки | E14: 41500 | G14: ЗП на руки | H14: 10000
A15: ЗП аванс | B15: 10003.55 | D15: ЗП аванс | E15: 10062.13 | G15: 1 с | H15: 7500
A16: ЗП первичка | B16: 10001.55 | D16: ЗП первичка | E16: 10062.12
A17: ЗП вторчка | B17: =B14-B15-B16 -> 11994.9 | D17: ЗП вторчка | E17: =E14-E15-E16 -> 21375.75
A18: Мониторинг | B18: =20*71 -> 1420 | D18: ЭРТХА
A19: НА РУКИ вторичка | B19: =B17+B18 -> 13414.9
G20: Итого | H20: =SUM(H14:H19) -> 17500 | J20: =B19+E21+H20 -> 52290.65
D21: НА РУКИ вторичка | E21: =E17+E18+E19+E20 -> 21375.75 | G21: =B19+E21 -> 34790.65
A23: Бычновой Наташе за март 2025 | D23: Лобанова Анна за март 2024 | G23: Колова за март 2024
A24: ЗП на руки | B24: 32000 | D24: ЗП на руки | E24: 41500 | G24: ЗП на руки | H24: 10000
A25: Аванс первичка | B25: 10001.55 | D25: Аванс первичка | E25: 10062.13 | G25: 1 с | H25: 7500
A26: ЗП первичка | B26: 10002.55 | D26: ЗП первичка | E26: 10062.12 | G26: Разовая премия за 2024 | H26: 5000
A27: ЗП вторчка | B27: =B24-B25-B26 -> 11995.9 | D27: К доплате ЗП вторичка | E27: =E24-E25-E26 -> 21375.75
A28: Мониторинг, 21 дн | B28: =21*72 -> 1512 | D28: Доходка-расходка | E28: 3000
A29: Отпускные вторичка | D29: ЭРТХА
A30: НА РУКИ вторичка | B30: =B27+B28+B29 -> 13507.9 | D30: налог МАМЫ | E30: 0 | G30: НА РУКИ вторичка | H30: =SUM(H24:H29) -> 22500 | J30: =B30+E32+H30 -> 65383.65
D31: Разовая премия за 2024 | E31: 5000
D32: НА РУКИ вторичка | E32: =E27+E28+E29+E30+E31 -> 29375.75
A35: Бычновой Наташе за апрель 2025 | D35: Лобанова Анна за апрель 2025 | G35: Колова за апрель 2025
A36: ЗП на руки | B36: 32000 | D36: ЗП на руки | E36: 41500 | G36: ЗП на руки | H36: 10000
A37: Аванс первичка | B37: 10001.55 | D37: Аванс первичка | E37: 10062.13 | G37: Собрание | H37: 800
A38: ЗП первичка | B38: 10002.55 | D38: ЗП первичка | E38: 10062.12 | G38: 1 с | H38: 7500
A39: К доплате ЗП вторичка | B39: =B36-B37-B38 -> 11995.9 | D39: К доплате ЗП вторичка | E39: =E36-E37-E38 -> 21375.75 | G39: Прием звонков 28,29,30 | H39: 3200
A40: Мониторинг | B40: =22*72 -> 1584 | D40: ЭРТХА | G40: Мониторинг 3 дня | H40: =3*72 -> 216
A41: Отпускные вторичка | B41: 4040 | D41: налог МАМЫ | F41: 4964.45 | G41: Надбавка по итогу 1 кв | H41: 131.77
